Workbook

Sheet correlation
A1: ref_name | B1: Use | D1: codec | E1: Use
A2: Buildings2.mp4 | B2: 1 | D2: AVS | E2: 1
A3: Chimera13_1000nit.mp4 | B3: 1 | D3: DCVC-RT | E3: 1
A4: Chimera2_1000nit.mp4 | B4: 1 | D4: EEM | E4: 1
A5: Chimera3_1000nit.mp4 | B5: 1 | D5: LTM | E5: 1
A6: Chimera4_1000nit.mp4 | B6: 1 | D6: NNVC | E6: 1
A7: Coffee1.mp4 | B7: 1 | D7: VTM | E7: 1
A8: DroneShowEnding.mp4 | B8: 1 | D8: AlphaVC-P | E8: 1
A9: FlyingBirds.mp4 | B9: 1
A10: Football1_1000nit.mp4 | B10: 1
A11: Fountain2.mp4 | B11: 1
A12: Nocturne1_1000nit.mp4 | B12: 1
A13: Smithy1_1000nit.mp4 | B13: 1
A14: Sparks2_1000nit.mp4 | B14: 1
A15: Sparks3_1000nit.mp4 | B15: 1
A16: TeaStall.mp4 | B16: 1
A18: Statistics | B18: Value
A19: # videos | B19: 305
A20: # metrics | B20: 6
A21: # rows with MOS | B21: =COUNT(mos_metrics!$F$2:$F$306)
A22: # rows included by controls | B22: =SUMPRODUCT(--(calc!$J$3:$J$306=TRUE))
A23: # source metric columns | B23: 6
A25: Metric | B25: PLCC | C25: SROCC | D25: KROCC | E25: RMSE | F25: Slope | G25: Intercept | H25: Nonblank source | I25: Use | J25: Direction | K25: N
A26: =mos_metrics!G$1 | B26: =IF($K26>=2,IFERROR(CORREL(calc!$M$3:$M$306,calc!$O$3:$O$306),""),"") | C26: =IF($K26>=2,IFERROR(CORREL(calc!$Q$3:$Q$306,calc!$R$3:$R$306),""),"") | D26: =IF($K26>=2,IFERROR(SUM(calc!$S$3:$S$306)/SQRT((($K26*($K26-1)/2)-(SUMPRODUCT(--(calc!$L$3:$L$306=TRUE),COUNTIF(calc!$Q$3:$Q$306,calc!$Q$3:$Q$306)-1)/2))*(($K26*($K26-1)/2)-(SUMPRODUCT(--(calc!$L$3:$L$306=TRUE),COUNTIF(calc!$R$3:$R$306,calc!$R$3:$R$306)-1)/2))),""),"") | E26: =IF($K26>=2,IFERROR(SQRT(SUM(calc!$P$3:$P$306)/$K26),""),"") | F26: =IF($K26>=2,IFERROR(SLOPE(calc!$M$3:$M$306,calc!$N$3:$N$306),""),"") | G26: =IF($K26>=2,IFERROR(INTERCEPT(calc!$M$3:$M$306,calc!$N$3:$N$306),""),"") | H26: =COUNT(mos_metrics!G$2:G$306) | I26: =IF($A26<>"",1,"") | J26: =IF($A26="DeltaE",-1,1) | K26: =SUMPRODUCT(--(calc!$L$3:$L$306=TRUE))
A27: =mos_metrics!H$1 | B27: =IF($K27>=2,IFERROR(CORREL(calc!$V$3:$V$306,calc!$X$3:$X$306),""),"") | C27: =IF($K27>=2,IFERROR(CORREL(calc!$Z$3:$Z$306,calc!$AA$3:$AA$306),""),"") | D27: =IF($K27>=2,IFERROR(SUM(calc!$AB$3:$AB$306)/SQRT((($K27*($K27-1)/2)-(SUMPRODUCT(--(calc!$U$3:$U$306=TRUE),COUNTIF(calc!$Z$3:$Z$306,calc!$Z$3:$Z$306)-1)/2))*(($K27*($K27-1)/2)-(SUMPRODUCT(--(calc!$U$3:$U$306=TRUE),COUNTIF(calc!$AA$3:$AA$306,calc!$AA$3:$AA$306)-1)/2))),""),"") | E27: =IF($K27>=2,IFERROR(SQRT(SUM(calc!$Y$3:$Y$306)/$K27),""),"") | F27: =IF($K27>=2,IFERROR(SLOPE(calc!$V$3:$V$306,calc!$W$3:$W$306),""),"") | G27: =IF($K27>=2,IFERROR(INTERCEPT(calc!$V$3:$V$306,calc!$W$3:$W$306),""),"") | H27: =COUNT(mos_metrics!H$2:H$306) | I27: =IF($A27<>"",1,"") | J27: =IF($A27="DeltaE",-1,1) | K27: =SUMPRODUCT(--(calc!$U$3:$U$306=TRUE))
A28: =mos_metrics!I$1 | B28: =IF($K28>=2,IFERROR(CORREL(calc!$AE$3:$AE$306,calc!$AG$3:$AG$306),""),"") | C28: =IF($K28>=2,IFERROR(CORREL(calc!$AI$3:$AI$306,calc!$AJ$3:$AJ$306),""),"") | D28: =IF($K28>=2,IFERROR(SUM(calc!$AK$3:$AK$306)/SQRT((($K28*($K28-1)/2)-(SUMPRODUCT(--(calc!$AD$3:$AD$306=TRUE),COUNTIF(calc!$AI$3:$AI$306,calc!$AI$3:$AI$306)-1)/2))*(($K28*($K28-1)/2)-(SUMPRODUCT(--(calc!$AD$3:$AD$306=TRUE),COUNTIF(calc!$AJ$3:$AJ$306,calc!$AJ$3:$AJ$306)-1)/2))),""),"") | E28: =IF($K28>=2,IFERROR(SQRT(SUM(calc!$AH$3:$AH$306)/$K28),""),"") | F28: =IF($K28>=2,IFERROR(SLOPE(calc!$AE$3:$AE$306,calc!$AF$3:$AF$306),""),"") | G28: =IF($K28>=2,IFERROR(INTERCEPT(calc!$AE$3:$AE$306,calc!$AF$3:$AF$306),""),"") | H28: =COUNT(mos_metrics!I$2:I$306) | I28: =IF($A28<>"",1,"") | J28: =IF($A28="DeltaE",-1,1) | K28: =SUMPRODUCT(--(calc!$AD$3:$AD$306=TRUE))
A29: =mos_metrics!J$1 | B29: =IF($K29>=2,IFERROR(CORREL(calc!$AN$3:$AN$306,calc!$AP$3:$AP$306),""),"") | C29: =IF($K29>=2,IFERROR(CORREL(calc!$AR$3:$AR$306,calc!$AS$3:$AS$306),""),"") | D29: =IF($K29>=2,IFERROR(SUM(calc!$AT$3:$AT$306)/SQRT((($K29*($K29-1)/2)-(SUMPRODUCT(--(calc!$AM$3:$AM$306=TRUE),COUNTIF(calc!$AR$3:$AR$306,calc!$AR$3:$AR$306)-1)/2))*(($K29*($K29-1)/2)-(SUMPRODUCT(--(calc!$AM$3:$AM$306=TRUE),COUNTIF(calc!$AS$3:$AS$306,calc!$AS$3:$AS$306)-1)/2))),""),"") | E29: =IF($K29>=2,IFERROR(SQRT(SUM(calc!$AQ$3:$AQ$306)/$K29),""),"") | F29: =IF($K29>=2,IFERROR(SLOPE(calc!$AN$3:$AN$306,calc!$AO$3:$AO$306),""),"") | G29: =IF($K29>=2,IFERROR(INTERCEPT(calc!$AN$3:$AN$306,calc!$AO$3:$AO$306),""),"") | H29: =COUNT(mos_metrics!J$2:J$306) | I29: =IF($A29<>"",1,"") | J29: =IF($A29="DeltaE",-1,1) | K29: =SUMPRODUCT(--(calc!$AM$3:$AM$306=TRUE))
A30: =mos_metrics!K$1 | B30: =IF($K30>=2,IFERROR(CORREL(calc!$AW$3:$AW$306,calc!$AY$3:$AY$306),""),"") | C30: =IF($K30>=2,IFERROR(CORREL(calc!$BA$3:$BA$306,calc!$BB$3:$BB$306),""),"") | D30: =IF($K30>=2,IFERROR(SUM(calc!$BC$3:$BC$306)/SQRT((($K30*($K30-1)/2)-(SUMPRODUCT(--(calc!$AV$3:$AV$306=TRUE),COUNTIF(calc!$BA$3:$BA$306,calc!$BA$3:$BA$306)-1)/2))*(($K30*($K30-1)/2)-(SUMPRODUCT(--(calc!$AV$3:$AV$306=TRUE),COUNTIF(calc!$BB$3:$BB$306,calc!$BB$3:$BB$306)-1)/2))),""),"") | E30: =IF($K30>=2,IFERROR(SQRT(SUM(calc!$AZ$3:$AZ$306)/$K30),""),"") | F30: =IF($K30>=2,IFERROR(SLOPE(calc!$AW$3:$AW$306,calc!$AX$3:$AX$306),""),"") | G30: =IF($K30>=2,IFERROR(INTERCEPT(calc!$AW$3:$AW$306,calc!$AX$3:$AX$306),""),"") | H30: =COUNT(mos_metrics!K$2:K$306) | I30: =IF($A30<>"",1,"") | J30: =IF($A30="DeltaE",-1,1) | K30: =SUMPRODUCT(--(calc!$AV$3:$AV$306=TRUE))
A31: =mos_metrics!L$1 | B31: =IF($K31>=2,IFERROR(CORREL(calc!$BF$3:$BF$306,calc!$BH$3:$BH$306),""),"") | C31: =IF($K31>=2,IFERROR(CORREL(calc!$BJ$3:$BJ$306,calc!$BK$3:$BK$306),""),"") | D31: =IF($K31>=2,IFERROR(SUM(calc!$BL$3:$BL$306)/SQRT((($K31*($K31-1)/2)-(SUMPRODUCT(--(calc!$BE$3:$BE$306=TRUE),COUNTIF(calc!$BJ$3:$BJ$306,calc!$BJ$3:$BJ$306)-1)/2))*(($K31*($K31-1)/2)-(SUMPRODUCT(--(calc!$BE$3:$BE$306=TRUE),COUNTIF(calc!$BK$3:$BK$306,calc!$BK$3:$BK$306)-1)/2))),""),"") | E31: =IF($K31>=2,IFERROR(SQRT(SUM(calc!$BI$3:$BI$306)/$K31),""),"") | F31: =IF($K31>=2,IFERROR(SLOPE(calc!$BF$3:$BF$306,calc!$BG$3:$BG$306),""),"") | G31: =IF($K31>=2,IFERROR(INTERCEPT(calc!$BF$3:$BF$306,calc!$BG$3:$BG$306),""),"") | H31: =COUNT(mos_metrics!L$2:L$306) | I31: =IF($A31<>"",1,"") | J31: =IF($A31="DeltaE",-1,1) | K31: =SUMPRODUCT(--(calc!$BE$3:$BE$306=TRUE))
A32: =mos_metrics!M$1 | B32: =IF($K32>=2,IFERROR(CORREL(calc!$BO$3:$BO$306,calc!$BQ$3:$BQ$306),""),"") | C32: =IF($K32>=2,IFERROR(CORREL(calc!$BS$3:$BS$306,calc!$BT$3:$BT$306),""),"") | D32: =IF($K32>=2,IFERROR(SUM(calc!$BU$3:$BU$306)/SQRT((($K32*($K32-1)/2)-(SUMPRODUCT(--(calc!$BN$3:$BN$306=TRUE),COUNTIF(calc!$BS$3:$BS$306,calc!$BS$3:$BS$306)-1)/2))*(($K32*($K32-1)/2)-(SUMPRODUCT(--(calc!$BN$3:$BN$306=TRUE),COUNTIF(calc!$BT$3:$BT$306,calc!$BT$3:$BT$306)-1)/2))),""),"") | E32: =IF($K32>=2,IFERROR(SQRT(SUM(calc!$BR$3:$BR$306)/$K32),""),"") | F32: =IF($K32>=2,IFERROR(SLOPE(calc!$BO$3:$BO$306,calc!$BP$3:$BP$306),""),"") | G32: =IF($K32>=2,IFERROR(INTERCEPT(calc!$BO$3:$BO$306,calc!$BP$3:$BP$306),""),"") | H32: =COUNT(mos_metrics!M$2:M$306) | I32: =IF($A32<>"",1,"") | J32: =IF($A32="DeltaE",-1,1) | K32: =SUMPRODUCT(--(calc!$BN$3:$BN$306=TRUE))

Sheet calc
A1: Source / MOS | G1: Selection flags | K1: PSNR_avg_score | T1: ColorVideoVDP_score | AC1: VMAF_score | AL1: WTPSNR_score | AU1: DeltaE_score | BD1: PSNR_L0100_score | BM1: FDIM_score
A2: KEY | B2: ref_name | C2: dis_name | D2: trc | E2: codec | F2: MOS | G2: ShowSeq | H2: ShowCodec | I2: ValidMOS | J2: UseBase | K2: raw | L2: valid | M2: mos_used | N2: score | O2: fit | P2: sq_error | Q2: mos_rank | R2: score_rank | S2: kendall_num | T2: raw | U2: valid | V2: mos_used | W2: score | X2: fit | Y2: sq_error | Z2: mos_rank | AA2: score_rank | AB2: kendall_num | AC2: raw | AD2: valid | AE2: mos_used | AF2: score | AG2: fit | AH2: sq_error | AI2: mos_rank | AJ2: score_rank | AK2: kendall_num | AL2: raw | AM2: valid | AN2: mos_used | AO2: score | AP2: fit | AQ2: sq_error | AR2: mos_rank | AS2: score_rank | AT2: kendall_num | AU2: raw | AV2: valid | AW2: mos_used | AX2: score | AY2: fit | AZ2: sq_error | BA2: mos_rank | BB2: score_rank | BC2: kendall_num | BD2: raw | BE2: valid | BF2: mos_used | BG2: score | BH2: fit | BI2: sq_error | BJ2: mos_rank | BK2: score_rank | BL2: kendall_num | BM2: raw | BN2: valid | BO2: mos_used | BP2: score | BQ2: fit | BR2: sq_error | BS2: mos_rank | BT2: score_rank | BU2: kendall_num
A3: =mos_metrics!A2 | B3: =mos_metrics!B2 | C3: =mos_metrics!C2 | D3: =mos_metrics!D2 | E3: =mos_metrics!E2 | F3: =mos_metrics!F2 | G3: =IF($B3="","",IFERROR(VLOOKUP($B3,correlation!$A$2:$B$16,2,FALSE),1)) | H3: =IF($E3="","",IFERROR(VLOOKUP($E3,correlation!$D$2:$E$8,2,FALSE),1)) | I3: =ISNUMBER($F3) | J3: =AND($G3=1,$H3=1,$I3) | K3: =IF(mos_metrics!G2="","",mos_metrics!G2) | L3: =AND($J3,ISNUMBER(K3),correlation!$I$26=1) | M3: =IF(L3,$F3,"") | N3: =IF(L3,K3*correlation!$J$26,"") | O3: =IF(AND(L3,ISNUMBER(correlation!$F$26)),N3*correlation!$F$26+correlation!$G$26,"") | P3: =IF(AND(L3,ISNUMBER(O3)),(M3-O3)^2,"") | Q3: =IF(L3,1+SUMPRODUCT(--(calc!$L$3:$L$306=TRUE),--(calc!$M$3:$M$306>M3))+(SUMPRODUCT(--(calc!$L$3:$L$306=TRUE),--(calc!$M$3:$M$306=M3))-1)/2,"") | R3: =IF(L3,1+SUMPRODUCT(--(calc!$L$3:$L$306=TRUE),--(calc!$N$3:$N$306>N3))+(SUMPRODUCT(--(calc!$L$3:$L$306=TRUE),--(calc!$N$3:$N$306=N3))-1)/2,"") | S3: =IF(L3,SUMPRODUCT(--(calc!$L$3:$L$306=TRUE),--(ROW(calc!$L$3:$L$306)>ROW(L3)),--(((calc!$Q$3:$Q$306>Q3)*(calc!$R$3:$R$306>R3)+(calc!$Q$3:$Q$306<Q3)*(calc!$R$3:$R$306<R3))>0))-SUMPRODUCT(--(calc!$L$3:$L$306=TRUE),--(ROW(calc!$L$3:$L$306)>ROW(L3)),--(((calc!$Q$3:$Q$306>Q3)*(calc!$R$3:$R$306<R3)+(calc!$Q$3:$Q$306<Q3)*(calc!$R$3:$R$306>R3))>0)),0) | T3: =IF(mos_metrics!H2="","",mos_metrics!H2) | U3: =AND($J3,ISNUMBER(T3),correlation!$I$27=1) | V3: =IF(U3,$F3,"") | W3: =IF(U3,T3*correlation!$J$27,"") | X3: =IF(AND(U3,ISNUMBER(correlation!$F$27)),W3*correlation!$F$27+correlation!$G$27,"") | Y3: =IF(AND(U3,ISNUMBER(X3)),(V3-X3)^2,"") | Z3: =IF(U3,1+SUMPRODUCT(--(calc!$U$3:$U$306=TRUE),--(calc!$V$3:$V$306>V3))+(SUMPRODUCT(--(calc!$U$3:$U$306=TRUE),--(calc!$V$3:$V$306=V3))-1)/2,"") | AA3: =IF(U3,1+SUMPRODUCT(--(calc!$U$3:$U$306=TRUE),--(calc!$W$3:$W$306>W3))+(SUMPRODUCT(--(calc!$U$3:$U$306=TRUE),--(calc!$W$3:$W$306=W3))-1)/2,"") | AB3: =IF(U3,SUMPRODUCT(--(calc!$U$3:$U$306=TRUE),--(ROW(calc!$U$3:$U$306)>ROW(U3)),--(((calc!$Z$3:$Z$306>Z3)*(calc!$AA$3:$AA$306>AA3)+(calc!$Z$3:$Z$306<Z3)*(calc!$AA$3:$AA$306<AA3))>0))-SUMPRODUCT(--(calc!$U$3:$U$306=TRUE),--(ROW(calc!$U$3:$U$306)>ROW(U3)),--(((calc!$Z$3:$Z$306>Z3)*(calc!$AA$3:$AA$306<AA3)+(calc!$Z$3:$Z$306<Z3)*(calc!$AA$3:$AA$306>AA3))>0)),0) | AC3: =IF(mos_metrics!I2="","",mos_metrics!I2) | AD3: =AND($J3,ISNUMBER(AC3),correlation!$I$28=1) | AE3: =IF(AD3,$F3,"") | AF3: =IF(AD3,AC3*correlation!$J$28,"") | AG3: =IF(AND(AD3,ISNUMBER(correlation!$F$28)),AF3*correlation!$F$28+correlation!$G$28,"") | AH3: =IF(AND(AD3,ISNUMBER(AG3)),(AE3-AG3)^2,"") | AI3: =IF(AD3,1+SUMPRODUCT(--(calc!$AD$3:$AD$306=TRUE),--(calc!$AE$3:$AE$306>AE3))+(SUMPRODUCT(--(calc!$AD$3:$AD$306=TRUE),--(calc!$AE$3:$AE$306=AE3))-1)/2,"") | AJ3: =IF(AD3,1+SUMPRODUCT(--(calc!$AD$3:$AD$306=TRUE),--(calc!$AF$3:$AF$306>AF3))+(SUMPRODUCT(--(calc!$AD$3:$AD$306=TRUE),--(calc!$AF$3:$AF$306=AF3))-1)/2,"") | AK3: =IF(AD3,SUMPRODUCT(--(calc!$AD$3:$AD$306=TRUE),--(ROW(calc!$AD$3:$AD$306)>ROW(AD3)),--(((calc!$AI$3:$AI$306>AI3)*(calc!$AJ$3:$AJ$306>AJ3)+(calc!$AI$3:$AI$306<AI3)*(calc!$AJ$3:$AJ$306<AJ3))>0))-SUMPRODUCT(--(calc!$AD$3:$AD$306=TRUE),--(ROW(calc!$AD$3:$AD$306)>ROW(AD3)),--(((calc!$AI$3:$AI$306>AI3)*(calc!$AJ$3:$AJ$306<AJ3)+(calc!$AI$3:$AI$306<AI3)*(calc!$AJ$3:$AJ$306>AJ3))>0)),0) | AL3: =IF(mos_metrics!J2="","",mos_metrics!J2) | AM3: =AND($J3,ISNUMBER(AL3),correlation!$I$29=1) | AN3: =IF(AM3,$F3,"") | AO3: =IF(AM3,AL3*correlation!$J$29,"") | AP3: =IF(AND(AM3,ISNUMBER(correlation!$F$29)),AO3*correlation!$F$29+correlation!$G$29,"") | AQ3: =IF(AND(AM3,ISNUMBER(AP3)),(AN3-AP3)^2,"") | AR3: =IF(AM3,1+SUMPRODUCT(--(calc!$AM$3:$AM$306=TRUE),--(calc!$AN$3:$AN$306>AN3))+(SUMPRODUCT(--(calc!$AM$3:$AM$306=TRUE),--(calc!$AN$3:$AN$306=AN3))-1)/2,"") | AS3: =IF(AM3,1+SUMPRODUCT(--(calc!$AM$3:$AM$306=TRUE),--(calc!$AO$3:$AO$306>AO3))+(SUMPRODUCT(--(calc!$AM$3:$AM$306=TRUE),--(calc!$AO$3:$AO$306=AO3))-1)/2,"") | AT3: =IF(AM3,SUMPRODUCT(--(calc!$AM$3:$AM$306=TRUE),--(ROW(calc!$AM$3:$AM$306)>ROW(AM3)),--(((calc!$AR$3:$AR$306>AR3)*(calc!$AS$3:$AS$306>AS3)+(calc!$AR$3:$AR$306<AR3)*(calc!$AS$3:$AS$306<AS3))>0))-SUMPRODUCT(--(calc!$AM$3:$AM$306=TRUE),--(ROW(calc!$AM$3:$AM$306)>ROW(AM3)),--(((calc!$AR$3:$AR$306>AR3)*(calc!$AS$3:$AS$306<AS3)+(calc!$AR$3:$AR$306<AR3)*(calc!$AS$3:$AS$306>AS3))>0)),0) | AU3: =IF(mos_metrics!K2="","",mos_metrics!K2) | AV3: =AND($J3,ISNUMBER(AU3),correlation!$I$30=1) | AW3: =IF(AV3,$F3,"") | AX3: =IF(AV3,AU3*correlation!$J$30,"") | AY3: =IF(AND(AV3,ISNUMBER(correlation!$F$30)),AX3*correlation!$F$30+correlation!$G$30,"") | AZ3: =IF(AND(AV3,ISNUMBER(AY3)),(AW3-AY3)^2,"") | BA3: =IF(AV3,1+SUMPRODUCT(--(calc!$AV$3:$AV$306=TRUE),--(calc!$AW$3:$AW$306>AW3))+(SUMPRODUCT(--(calc!$AV$3:$AV$306=TRUE),--(calc!$AW$3:$AW$306=AW3))-1)/2,"") | BB3: =IF(AV3,1+SUMPRODUCT(--(calc!$AV$3:$AV$306=TRUE),--(calc!$AX$3:$AX$306>AX3))+(SUMPRODUCT(--(calc!$AV$3:$AV$306=TRUE),--(calc!$AX$3:$AX$306=AX3))-1)/2,"") | BC3: =IF(AV3,SUMPRODUCT(--(calc!$AV$3:$AV$306=TRUE),--(ROW(calc!$AV$3:$AV$306)>ROW(AV3)),--(((calc!$BA$3:$BA$306>BA3)*(calc!$BB$3:$BB$306>BB3)+(calc!$BA$3:$BA$306<BA3)*(calc!$BB$3:$BB$306<BB3))>0))-SUMPRODUCT(--(calc!$AV$3:$AV$306=TRUE),--(ROW(calc!$AV$3:$AV$306)>ROW(AV3)),--(((calc!$BA$3:$BA$306>BA3)*(calc!$BB$3:$BB$306<BB3)+(calc!$BA$3:$BA$306<BA3)*(calc!$BB$3:$BB$306>BB3))>0)),0) | BD3: =IF(mos_metrics!L2="","",mos_metrics!L2) | BE3: =AND($J3,ISNUMBER(BD3),correlation!$I$31=1) | BF3: =IF(BE3,$F3,"") | BG3: =IF(BE3,BD3*correlation!$J$31,"") | BH3: =IF(AND(BE3,ISNUMBER(correlation!$F$31)),BG3*correlation!$F$31+correlation!$G$31,"") | BI3: =IF(AND(BE3,ISNUMBER(BH3)),(BF3-BH3)^2,"") | BJ3: =IF(BE3,1+SUMPRODUCT(--(calc!$BE$3:$BE$306=TRUE),--(calc!$BF$3:$BF$306>BF3))+(SUMPRODUCT(--(calc!$BE$3:$BE$306=TRUE),--(calc!$BF$3:$BF$306=BF3))-1)/2,"") | BK3: =IF(BE3,1+SUMPRODUCT(--(calc!$BE$3:$BE$306=TRUE),--(calc!$BG$3:$BG$306>BG3))+(SUMPRODUCT(--(calc!$BE$3:$BE$306=TRUE),--(calc!$BG$3:$BG$306=BG3))-1)/2,"") | BL3: =IF(BE3,SUMPRODUCT(--(calc!$BE$3:$BE$306=TRUE),--(ROW(calc!$BE$3:$BE$306)>ROW(BE3)),--(((calc!$BJ$3:$BJ$306>BJ3)*(calc!$BK$3:$BK$306>BK3)+(calc!$BJ$3:$BJ$306<BJ3)*(calc!$BK$3:$BK$306<BK3))>0))-SUMPRODUCT(--(calc!$BE$3:$BE$306=TRUE),--(ROW(calc!$BE$3:$BE$306)>ROW(BE3)),--(((calc!$BJ$3:$BJ$306>BJ3)*(calc!$BK$3:$BK$306<BK3)+(calc!$BJ$3:$BJ$306<BJ3)*(calc!$BK$3:$BK$306>BK3))>0)),0) | BM3: =IF(mos_metrics!M2="","",mos_metrics!M2) | BN3: =AND($J3,ISNUMBER(BM3),correlation!$I$32=1) | BO3: =IF(BN3,$F3,"") | BP3: =IF(BN3,BM3*correlation!$J$32,"") | BQ3: =IF(AND(BN3,ISNUMBER(correlation!$F$32)),BP3*correlation!$F$32+correlation!$G$32,"") | BR3: =IF(AND(BN3,ISNUMBER(BQ3)),(BO3-BQ3)^2,"") | BS3: =IF(BN3,1+SUMPRODUCT(--(calc!$BN$3:$BN$306=TRUE),--(calc!$BO$3:$BO$306>BO3))+(SUMPRODUCT(--(calc!$BN$3:$BN$306=TRUE),--(calc!$BO$3:$BO$306=BO3))-1)/2,"") | BT3: =IF(BN3,1+SUMPRODUCT(--(calc!$BN$3:$BN$306=TRUE),--(calc!$BP$3:$BP$306>BP3))+(SUMPRODUCT(--(calc!$BN$3:$BN$306=TRUE),--(calc!$BP$3:$BP$306=BP3))-1)/2,"") | BU3: =IF(BN3,SUMPRODUCT(--(calc!$BN$3:$BN$306=TRUE),--(ROW(calc!$BN$3:$BN$306)>ROW(BN3)),--(((calc!$BS$3:$BS$306>BS3)*(calc!$BT$3:$BT$306>BT3)+(calc!$BS$3:$BS$306<BS3)*(calc!$BT$3:$BT$306<BT3))>0))-SUMPRODUCT(--(calc!$BN$3:$BN$306=TRUE),--(ROW(calc!$BN$3:$BN$306)>ROW(BN3)),--(((calc!$BS$3:$BS$306>BS3)*(calc!$BT$3:$BT$306<BT3)+(calc!$BS$3:$BS$306<BS3)*(calc!$BT$3:$BT$306>BT3))>0)),0)
A4: =mos_metrics!A3 | B4: =mos_metrics!B3 | C4: =mos_metrics!C3 | D4: =mos_metrics!D3 | E4: =mos_metrics!E3 | F4: =mos_metrics!F3 | G4: =IF($B4="","",IFERROR(VLOOKUP($B4,correlation!$A$2:$B$16,2,FALSE),1)) | H4: =IF($E4="","",IFERROR(VLOOKUP($E4,correlation!$D$2:$E$8,2,FALSE),1)) | I4: =ISNUMBER($F4) | J4: =AND($G4=1,$H4=1,$I4) | K4: =IF(mos_metrics!G3="","",mos_metrics!G3) | L4: =AND($J4,ISNUMBER(K4),correlation!$I$26=1) | M4: =IF(L4,$F4,"") | N4: =IF(L4,K4*correlation!$J$26,"") | O4: =IF(AND(L4,ISNUMBER(correlation!$F$26)),N4*correlation!$F$26+correlation!$G$26,"") | P4: =IF(AND(L4,ISNUMBER(O4)),(M4-O4)^2,"") | Q4: =IF(L4,1+SUMPRODUCT(--(calc!$L$3:$L$306=TRUE),--(calc!$M$3:$M$306>M4))+(SUMPRODUCT(--(calc!$L$3:$L$306=TRUE),--(calc!$M$3:$M$306=M4))-1)/2,"") | R4: =IF(L4,1+SUMPRODUCT(--(calc!$L$3:$L$306=TRUE),--(calc!$N$3:$N$306>N4))+(SUMPRODUCT(--(calc!$L$3:$L$306=TRUE),--(calc!$N$3:$N$306=N4))-1)/2,"") | S4: =IF(L4,SUMPRODUCT(--(calc!$L$3:$L$306=TRUE),--(ROW(calc!$L$3:$L$306)>ROW(L4)),--(((calc!$Q$3:$Q$306>Q4)*(calc!$R$3:$R$306>R4)+(calc!$Q$3:$Q$306<Q4)*(calc!$R$3:$R$306<R4))>0))-SUMPRODUCT(--(calc!$L$3:$L$306=TRUE),--(ROW(calc!$L$3:$L$306)>ROW(L4)),--(((calc!$Q$3:$Q$306>Q4)*(calc!$R$3:$R$306<R4)+(calc!$Q$3:$Q$306<Q4)*(calc!$R$3:$R$306>R4))>0)),0) | T4: =IF(mos_metrics!H3="","",mos_metrics!H3) | U4: =AND($J4,ISNUMBER(T4),correlation!$I$27=1) | V4: =IF(U4,$F4,"") | W4: =IF(U4,T4*correlation!$J$27,"") | X4: =IF(AND(U4,ISNUMBER(correlation!$F$27)),W4*correlation!$F$27+correlation!$G$27,"") | Y4: =IF(AND(U4,ISNUMBER(X4)),(V4-X4)^2,"") | Z4: =IF(U4,1+SUMPRODUCT(--(calc!$U$3:$U$306=TRUE),--(calc!$V$3:$V$306>V4))+(SUMPRODUCT(--(calc!$U$3:$U$306=TRUE),--(calc!$V$3:$V$306=V4))-1)/2,"") | AA4: =IF(U4,1+SUMPRODUCT(--(calc!$U$3:$U$306=TRUE),--(calc!$W$3:$W$306>W4))+(SUMPRODUCT(--(calc!$U$3:$U$306=TRUE),--(calc!$W$3:$W$306=W4))-1)/2,"") | AB4: =IF(U4,SUMPRODUCT(--(calc!$U$3:$U$306=TRUE),--(ROW(calc!$U$3:$U$306)>ROW(U4)),--(((calc!$Z$3:$Z$306>Z4)*(calc!$AA$3:$AA$306>AA4)+(calc!$Z$3:$Z$306<Z4)*(calc!$AA$3:$AA$306<AA4))>0))-SUMPRODUCT(--(calc!$U$3:$U$306=TRUE),--(ROW(calc!$U$3:$U$306)>ROW(U4)),--(((calc!$Z$3:$Z$306>Z4)*(calc!$AA$3:$AA$306<AA4)+(calc!$Z$3:$Z$306<Z4)*(calc!$AA$3:$AA$306>AA4))>0)),0) | AC4: =IF(mos_metrics!I3="","",mos_metrics!I3) | AD4: =AND($J4,ISNUMBER(AC4),correlation!$I$28=1) | AE4: =IF(AD4,$F4,"") | AF4: =IF(AD4,AC4*correlation!$J$28,"") | AG4: =IF(AND(AD4,ISNUMBER(correlation!$F$28)),AF4*correlation!$F$28+correlation!$G$28,"") | AH4: =IF(AND(AD4,ISNUMBER(AG4)),(AE4-AG4)^2,"") | AI4: =IF(AD4,1+SUMPRODUCT(--(calc!$AD$3:$AD$306=TRUE),--(calc!$AE$3:$AE$306>AE4))+(SUMPRODUCT(--(calc!$AD$3:$AD$306=TRUE),--(calc!$AE$3:$AE$306=AE4))-1)/2,"") | AJ4: =IF(AD4,1+SUMPRODUCT(--(calc!$AD$3:$AD$306=TRUE),--(calc!$AF$3:$AF$306>AF4))+(SUMPRODUCT(--(calc!$AD$3:$AD$306=TRUE),--(calc!$AF$3:$AF$306=AF4))-1)/2,"") | AK4: =IF(AD4,SUMPRODUCT(--(calc!$AD$3:$AD$306=TRUE),--(ROW(calc!$AD$3:$AD$306)>ROW(AD4)),--(((calc!$AI$3:$AI$306>AI4)*(calc!$AJ$3:$AJ$306>AJ4)+(calc!$AI$3:$AI$306<AI4)*(calc!$AJ$3:$AJ$306<AJ4))>0))-SUMPRODUCT(--(calc!$AD$3:$AD$306=TRUE),--(ROW(calc!$AD$3:$AD$306)>ROW(AD4)),--(((calc!$AI$3:$AI$306>AI4)*(calc!$AJ$3:$AJ$306<AJ4)+(calc!$AI$3:$AI$306<AI4)*(calc!$AJ$3:$AJ$306>AJ4))>0)),0) | AL4: =IF(mos_metrics!J3="","",mos_metrics!J3) | AM4: =AND($J4,ISNUMBER(AL4),correlation!$I$29=1) | AN4: =IF(AM4,$F4,"") | AO4: =IF(AM4,AL4*correlation!$J$29,"") | AP4: =IF(AND(AM4,ISNUMBER(correlation!$F$29)),AO4*correlation!$F$29+correlation!$G$29,"") | AQ4: =IF(AND(AM4,ISNUMBER(AP4)),(AN4-AP4)^2,"") | AR4: =IF(AM4,1+SUMPRODUCT(--(calc!$AM$3:$AM$306=TRUE),--(calc!$AN$3:$AN$306>AN4))+(SUMPRODUCT(--(calc!$AM$3:$AM$306=TRUE),--(calc!$AN$3:$AN$306=AN4))-1)/2,"") | AS4: =IF(AM4,1+SUMPRODUCT(--(calc!$AM$3:$AM$306=TRUE),--(calc!$AO$3:$AO$306>AO4))+(SUMPRODUCT(--(calc!$AM$3:$AM$306=TRUE),--(calc!$AO$3:$AO$306=AO4))-1)/2,"") | AT4: =IF(AM4,SUMPRODUCT(--(calc!$AM$3:$AM$306=TRUE),--(ROW(calc!$AM$3:$AM$306)>ROW(AM4)),--(((calc!$AR$3:$AR$306>AR4)*(calc!$AS$3:$AS$306>AS4)+(calc!$AR$3:$AR$306<AR4)*(calc!$AS$3:$AS$306<AS4))>0))-SUMPRODUCT(--(calc!$AM$3:$AM$306=TRUE),--(ROW(calc!$AM$3:$AM$306)>ROW(AM4)),--(((calc!$AR$3:$AR$306>AR4)*(calc!$AS$3:$AS$306<AS4)+(calc!$AR$3:$AR$306<AR4)*(calc!$AS$3:$AS$306>AS4))>0)),0) | AU4: =IF(mos_metrics!K3="","",mos_metrics!K3) | AV4: =AND($J4,ISNUMBER(AU4),correlation!$I$30=1) | AW4: =IF(AV4,$F4,"") | AX4: =IF(AV4,AU4*correlation!$J$30,"") | AY4: =IF(AND(AV4,ISNUMBER(correlation!$F$30)),AX4*correlation!$F$30+correlation!$G$30,"") | AZ4: =IF(AND(AV4,ISNUMBER(AY4)),(AW4-AY4)^2,"") | BA4: =IF(AV4,1+SUMPRODUCT(--(calc!$AV$3:$AV$306=TRUE),--(calc!$AW$3:$AW$306>AW4))+(SUMPRODUCT(--(calc!$AV$3:$AV$306=TRUE),--(calc!$AW$3:$AW$306=AW4))-1)/2,"") | BB4: =IF(AV4,1+SUMPRODUCT(--(calc!$AV$3:$AV$306=TRUE),--(calc!$AX$3:$AX$306>AX4))+(SUMPRODUCT(--(calc!$AV$3:$AV$306=TRUE),--(calc!$AX$3:$AX$306=AX4))-1)/2,"") | BC4: =IF(AV4,SUMPRODUCT(--(calc!$AV$3:$AV$306=TRUE),--(ROW(calc!$AV$3:$AV$306)>ROW(AV4)),--(((calc!$BA$3:$BA$306>BA4)*(calc!$BB$3:$BB$306>BB4)+(calc!$BA$3:$BA$306<BA4)*(calc!$BB$3:$BB$306<BB4))>0))-SUMPRODUCT(--(calc!$AV$3:$AV$306=TRUE),--(ROW(calc!$AV$3:$AV$306)>ROW(AV4)),--(((calc!$BA$3:$BA$306>BA4)*(calc!$BB$3:$BB$306<BB4)+(calc!$BA$3:$BA$306<BA4)*(calc!$BB$3:$BB$306>BB4))>0)),0) | BD4: =IF(mos_metrics!L3="","",mos_metrics!L3) | BE4: =AND($J4,ISNUMBER(BD4),correlation!$I$31=1) | BF4: =IF(BE4,$F4,"") | BG4: =IF(BE4,BD4*correlation!$J$31,"") | BH4: =IF(AND(BE4,ISNUMBER(correlation!$F$31)),BG4*correlation!$F$31+correlation!$G$31,"") | BI4: =IF(AND(BE4,ISNUMBER(BH4)),(BF4-BH4)^2,"") | BJ4: =IF(BE4,1+SUMPRODUCT(--(calc!$BE$3:$BE$306=TRUE),--(calc!$BF$3:$BF$306>BF4))+(SUMPRODUCT(--(calc!$BE$3:$BE$306=TRUE),--(calc!$BF$3:$BF$306=BF4))-1)/2,"") | BK4: =IF(BE4,1+SUMPRODUCT(--(calc!$BE$3:$BE$306=TRUE),--(calc!$BG$3:$BG$306>BG4))+(SUMPRODUCT(--(calc!$BE$3:$BE$306=TRUE),--(calc!$BG$3:$BG$306=BG4))-1)/2,"") | BL4: =IF(BE4,SUMPRODUCT(--(calc!$BE$3:$BE$306=TRUE),--(ROW(calc!$BE$3:$BE$306)>ROW(BE4)),--(((calc!$BJ$3:$BJ$306>BJ4)*(calc!$BK$3:$BK$306>BK4)+(calc!$BJ$3:$BJ$306<BJ4)*(calc!$BK$3:$BK$306<BK4))>0))-SUMPRODUCT(--(calc!$BE$3:$BE$306=TRUE),--(ROW(calc!$BE$3:$BE$306)>ROW(BE4)),--(((calc!$BJ$3:$BJ$306>BJ4)*(calc!$BK$3:$BK$306<BK4)+(calc!$BJ$3:$BJ$306<BJ4)*(calc!$BK$3:$BK$306>BK4))>0)),0) | BM4: =IF(mos_metrics!M3="","",mos_metrics!M3) | BN4: =AND($J4,ISNUMBER(BM4),correlation!$I$32=1) | BO4: =IF(BN4,$F4,"") | BP4: =IF(BN4,BM4*correlation!$J$32,"") | BQ4: =IF(AND(BN4,ISNUMBER(correlation!$F$32)),BP4*correlation!$F$32+correlation!$G$32,"") | BR4: =IF(AND(BN4,ISNUMBER(BQ4)),(BO4-BQ4)^2,"") | BS4: =IF(BN4,1+SUMPRODUCT(--(calc!$BN$3:$BN$306=TRUE),--(calc!$BO$3:$BO$306>BO4))+(SUMPRODUCT(--(calc!$BN$3:$BN$306=TRUE),--(calc!$BO$3:$BO$306=BO4))-1)/2,"") | BT4: =IF(BN4,1+SUMPRODUCT(--(calc!$BN$3:$BN$306=TRUE),--(calc!$BP$3:$BP$306>BP4))+(SUMPRODUCT(--(calc!$BN$3:$BN$306=TRUE),--(calc!$BP$3:$BP$306=BP4))-1)/2,"") | BU4: =IF(BN4,SUMPRODUCT(--(calc!$BN$3:$BN$306=TRUE),--(ROW(calc!$BN$3:$BN$306)>ROW(BN4)),--(((calc!$BS$3:$BS$306>BS4)*(calc!$BT$3:$BT$306>BT4)+(calc!$BS$3:$BS$306<BS4)*(calc!$BT$3:$BT$306<BT4))>0))-SUMPRODUCT(--(calc!$BN$3:$BN$306=TRUE),--(ROW(calc!$BN$3:$BN$306)>ROW(BN4)),--(((calc!$BS$3:$BS$306>BS4)*(calc!$BT$3:$BT$306<BT4)+(calc!$BS$3:$BS$306<BS4)*(calc!$BT$3:$BT$306>BT4))>0)),0)
A5: =mos_metrics!A4 | B5: =mos_metrics!B4 | C5: =mos_metrics!C4 | D5: =mos_metrics!D4 | E5: =mos_metrics!E4 | F5: =mos_metrics!F4 | G5: =IF($B5="","",IFERROR(VLOOKUP($B5,correlation!$A$2:$B$16,2,FALSE),1)) | H5: =IF($E5="","",IFERROR(VLOOKUP($E5,correlation!$D$2:$E$8,2,FALSE),1)) | I5: =ISNUMBER($F5) | J5: =AND($G5=1,$H5=1,$I5) | K5: =IF(mos_metrics!G4="","",mos_metrics!G4) | L5: =AND($J5,ISNUMBER(K5),correlation!$I$26=1) | M5: =IF(L5,$F5,"") | N5: =IF(L5,K5*correlation!$J$26,"") | O5: =IF(AND(L5,ISNUMBER(correlation!$F$26)),N5*correlation!$F$26+correlation!$G$26,"") | P5: =IF(AND(L5,ISNUMBER(O5)),(M5-O5)^2,"") | Q5: =IF(L5,1+SUMPRODUCT(--(calc!$L$3:$L$306=TRUE),--(calc!$M$3:$M$306>M5))+(SUMPRODUCT(--(calc!$L$3:$L$306=TRUE),--(calc!$M$3:$M$306=M5))-1)/2,"") | R5: =IF(L5,1+SUMPRODUCT(--(calc!$L$3:$L$306=TRUE),--(calc!$N$3:$N$306>N5))+(SUMPRODUCT(--(calc!$L$3:$L$306=TRUE),--(calc!$N$3:$N$306=N5))-1)/2,"") | S5: =IF(L5,SUMPRODUCT(--(calc!$L$3:$L$306=TRUE),--(ROW(calc!$L$3:$L$306)>ROW(L5)),--(((calc!$Q$3:$Q$306>Q5)*(calc!$R$3:$R$306>R5)+(calc!$Q$3:$Q$306<Q5)*(calc!$R$3:$R$306<R5))>0))-SUMPRODUCT(--(calc!$L$3:$L$306=TRUE),--(ROW(calc!$L$3:$L$306)>ROW(L5)),--(((calc!$Q$3:$Q$306>Q5)*(calc!$R$3:$R$306<R5)+(calc!$Q$3:$Q$306<Q5)*(calc!$R$3:$R$306>R5))>0)),0) | T5: =IF(mos_metrics!H4="","",mos_metrics!H4) | U5: =AND($J5,ISNUMBER(T5),correlation!$I$27=1) | V5: =IF(U5,$F5,"") | W5: =IF(U5,T5*correlation!$J$27,"") | X5: =IF(AND(U5,ISNUMBER(correlation!$F$27)),W5*correlation!$F$27+correlation!$G$27,"") | Y5: =IF(AND(U5,ISNUMBER(X5)),(V5-X5)^2,"") | Z5: =IF(U5,1+SUMPRODUCT(--(calc!$U$3:$U$306=TRUE),--(calc!$V$3:$V$306>V5))+(SUMPRODUCT(--(calc!$U$3:$U$306=TRUE),--(calc!$V$3:$V$306=V5))-1)/2,"") | AA5: =IF(U5,1+SUMPRODUCT(--(calc!$U$3:$U$306=TRUE),--(calc!$W$3:$W$306>W5))+(SUMPRODUCT(--(calc!$U$3:$U$306=TRUE),--(calc!$W$3:$W$306=W5))-1)/2,"") | AB5: =IF(U5,SUMPRODUCT(--(calc!$U$3:$U$306=TRUE),--(ROW(calc!$U$3:$U$306)>ROW(U5)),--(((calc!$Z$3:$Z$306>Z5)*(calc!$AA$3:$AA$306>AA5)+(calc!$Z$3:$Z$306<Z5)*(calc!$AA$3:$AA$306<AA5))>0))-SUMPRODUCT(--(calc!$U$3:$U$306=TRUE),--(ROW(calc!$U$3:$U$306)>ROW(U5)),--(((calc!$Z$3:$Z$306>Z5)*(calc!$AA$3:$AA$306<AA5)+(calc!$Z$3:$Z$306<Z5)*(calc!$AA$3:$AA$306>AA5))>0)),0) | AC5: =IF(mos_metrics!I4="","",mos_metrics!I4) | AD5: =AND($J5,ISNUMBER(AC5),correlation!$I$28=1) | AE5: =IF(AD5,$F5,"") | AF5: =IF(AD5,AC5*correlation!$J$28,"") | AG5: =IF(AND(AD5,ISNUMBER(correlation!$F$28)),AF5*correlation!$F$28+correlation!$G$28,"") | AH5: =IF(AND(AD5,ISNUMBER(AG5)),(AE5-AG5)^2,"") | AI5: =IF(AD5,1+SUMPRODUCT(--(calc!$AD$3:$AD$306=TRUE),--(calc!$AE$3:$AE$306>AE5))+(SUMPRODUCT(--(calc!$AD$3:$AD$306=TRUE),--(calc!$AE$3:$AE$306=AE5))-1)/2,"") | AJ5: =IF(AD5,1+SUMPRODUCT(--(calc!$AD$3:$AD$306=TRUE),--(calc!$AF$3:$AF$306>AF5))+(SUMPRODUCT(--(calc!$AD$3:$AD$306=TRUE),--(calc!$AF$3:$AF$306=AF5))-1)/2,"") | AK5: =IF(AD5,SUMPRODUCT(--(calc!$AD$3:$AD$306=TRUE),--(ROW(calc!$AD$3:$AD$306)>ROW(AD5)),--(((calc!$AI$3:$AI$306>AI5)*(calc!$AJ$3:$AJ$306>AJ5)+(calc!$AI$3:$AI$306<AI5)*(calc!$AJ$3:$AJ$306<AJ5))>0))-SUMPRODUCT(--(calc!$AD$3:$AD$306=TRUE),--(ROW(calc!$AD$3:$AD$306)>ROW(AD5)),--(((calc!$AI$3:$AI$306>AI5)*(calc!$AJ$3:$AJ$306<AJ5)+(calc!$AI$3:$AI$306<AI5)*(calc!$AJ$3:$AJ$306>AJ5))>0)),0) | AL5: =IF(mos_metrics!J4="","",mos_metrics!J4) | AM5: =AND($J5,ISNUMBER(AL5),correlation!$I$29=1) | AN5: =IF(AM5,$F5,"") | AO5: =IF(AM5,AL5*correlation!$J$29,"") | AP5: =IF(AND(AM5,ISNUMBER(correlation!$F$29)),AO5*correlation!$F$29+correlation!$G$29,"") | AQ5: =IF(AND(AM5,ISNUMBER(AP5)),(AN5-AP5)^2,"") | AR5: =IF(AM5,1+SUMPRODUCT(--(calc!$AM$3:$AM$306=TRUE),--(calc!$AN$3:$AN$306>AN5))+(SUMPRODUCT(--(calc!$AM$3:$AM$306=TRUE),--(calc!$AN$3:$AN$306=AN5))-1)/2,"") | AS5: =IF(AM5,1+SUMPRODUCT(--(calc!$AM$3:$AM$306=TRUE),--(calc!$AO$3:$AO$306>AO5))+(SUMPRODUCT(--(calc!$AM$3:$AM$306=TRUE),--(calc!$AO$3:$AO$306=AO5))-1)/2,"") | AT5: =IF(AM5,SUMPRODUCT(--(calc!$AM$3:$AM$306=TRUE),--(ROW(calc!$AM$3:$AM$306)>ROW(AM5)),--(((calc!$AR$3:$AR$306>AR5)*(calc!$AS$3:$AS$306>AS5)+(calc!$AR$3:$AR$306<AR5)*(calc!$AS$3:$AS$306<AS5))>0))-SUMPRODUCT(--(calc!$AM$3:$AM$306=TRUE),--(ROW(calc!$AM$3:$AM$306)>ROW(AM5)),--(((calc!$AR$3:$AR$306>AR5)*(calc!$AS$3:$AS$306<AS5)+(calc!$AR$3:$AR$306<AR5)*(calc!$AS$3:$AS$306>AS5))>0)),0) | AU5: =IF(mos_metrics!K4="","",mos_metrics!K4) | AV5: =AND($J5,ISNUMBER(AU5),correlation!$I$30=1) | AW5: =IF(AV5,$F5,"") | AX5: =IF(AV5,AU5*correlation!$J$30,"") | AY5: =IF(AND(AV5,ISNUMBER(correlation!$F$30)),AX5*correlation!$F$30+correlation!$G$30,"") | AZ5: =IF(AND(AV5,ISNUMBER(AY5)),(AW5-AY5)^2,"") | BA5: =IF(AV5,1+SUMPRODUCT(--(calc!$AV$3:$AV$306=TRUE),--(calc!$AW$3:$AW$306>AW5))+(SUMPRODUCT(--(calc!$AV$3:$AV$306=TRUE),--(calc!$AW$3:$AW$306=AW5))-1)/2,"") | BB5: =IF(AV5,1+SUMPRODUCT(--(calc!$AV$3:$AV$306=TRUE),--(calc!$AX$3:$AX$306>AX5))+(SUMPRODUCT(--(calc!$AV$3:$AV$306=TRUE),--(calc!$AX$3:$AX$306=AX5))-1)/2,"") | BC5: =IF(AV5,SUMPRODUCT(--(calc!$AV$3:$AV$306=TRUE),--(ROW(calc!$AV$3:$AV$306)>ROW(AV5)),--(((calc!$BA$3:$BA$306>BA5)*(calc!$BB$3:$BB$306>BB5)+(calc!$BA$3:$BA$306<BA5)*(calc!$BB$3:$BB$306<BB5))>0))-SUMPRODUCT(--(calc!$AV$3:$AV$306=TRUE),--(ROW(calc!$AV$3:$AV$306)>ROW(AV5)),--(((calc!$BA$3:$BA$306>BA5)*(calc!$BB$3:$BB$306<BB5)+(calc!$BA$3:$BA$306<BA5)*(calc!$BB$3:$BB$306>BB5))>0)),0) | BD5: =IF(mos_metrics!L4="","",mos_metrics!L4) | BE5: =AND($J5,ISNUMBER(BD5),correlation!$I$31=1) | BF5: =IF(BE5,$F5,"") | BG5: =IF(BE5,BD5*correlation!$J$31,"") | BH5: =IF(AND(BE5,ISNUMBER(correlation!$F$31)),BG5*correlation!$F$31+correlation!$G$31,"") | BI5: =IF(AND(BE5,ISNUMBER(BH5)),(BF5-BH5)^2,"") | BJ5: =IF(BE5,1+SUMPRODUCT(--(calc!$BE$3:$BE$306=TRUE),--(calc!$BF$3:$BF$306>BF5))+(SUMPRODUCT(--(calc!$BE$3:$BE$306=TRUE),--(calc!$BF$3:$BF$306=BF5))-1)/2,"") | BK5: =IF(BE5,1+SUMPRODUCT(--(calc!$BE$3:$BE$306=TRUE),--(calc!$BG$3:$BG$306>BG5))+(SUMPRODUCT(--(calc!$BE$3:$BE$306=TRUE),--(calc!$BG$3:$BG$306=BG5))-1)/2,"") | BL5: =IF(BE5,SUMPRODUCT(--(calc!$BE$3:$BE$306=TRUE),--(ROW(calc!$BE$3:$BE$306)>ROW(BE5)),--(((calc!$BJ$3:$BJ$306>BJ5)*(calc!$BK$3:$BK$306>BK5)+(calc!$BJ$3:$BJ$306<BJ5)*(calc!$BK$3:$BK$306<BK5))>0))-SUMPRODUCT(--(calc!$BE$3:$BE$306=TRUE),--(ROW(calc!$BE$3:$BE$306)>ROW(BE5)),--(((calc!$BJ$3:$BJ$306>BJ5)*(calc!$BK$3:$BK$306<BK5)+(calc!$BJ$3:$BJ$306<BJ5)*(calc!$BK$3:$BK$306>BK5))>0)),0) | BM5: =IF(mos_metrics!M4="","",mos_metrics!M4) | BN5: =AND($J5,ISNUMBER(BM5),correlation!$I$32=1) | BO5: =IF(BN5,$F5,"") | BP5: =IF(BN5,BM5*correlation!$J$32,"") | BQ5: =IF(AND(BN5,ISNUMBER(correlation!$F$32)),BP5*correlation!$F$32+correlation!$G$32,"") | BR5: =IF(AND(BN5,ISNUMBER(BQ5)),(BO5-BQ5)^2,"") | BS5: =IF(BN5,1+SUMPRODUCT(--(calc!$BN$3:$BN$306=TRUE),--(calc!$BO$3:$BO$306>BO5))+(SUMPRODUCT(--(calc!$BN$3:$BN$306=TRUE),--(calc!$BO$3:$BO$306=BO5))-1)/2,"") | BT5: =IF(BN5,1+SUMPRODUCT(--(calc!$BN$3:$BN$306=TRUE),--(calc!$BP$3:$BP$306>BP5))+(SUMPRODUCT(--(calc!$BN$3:$BN$306=TRUE),--(calc!$BP$3:$BP$306=BP5))-1)/2,"") | BU5: =IF(BN5,SUMPRODUCT(--(calc!$BN$3:$BN$306=TRUE),--(ROW(calc!$BN$3:$BN$306)>ROW(BN5)),--(((calc!$BS$3:$BS$306>BS5)*(calc!$BT$3:$BT$306>BT5)+(calc!$BS$3:$BS$306<BS5)*(calc!$BT$3:$BT$306<BT5))>0))-SUMPRODUCT(--(calc!$BN$3:$BN$306=TRUE),--(ROW(calc!$BN$3:$BN$306)>ROW(BN5)),--(((calc!$BS$3:$BS$306>BS5)*(calc!$BT$3:$BT$306<BT5)+(calc!$BS$3:$BS$306<BS5)*(calc!$BT$3:$BT$306>BT5))>0)),0)
A6: =mos_metrics!A5 | B6: =mos_metrics!B5 | C6: =mos_metrics!C5 | D6: =mos_metrics!D5 | E6: =mos_metrics!E5 | F6: =mos_metrics!F5 | G6: =IF($B6="","",IFERROR(VLOOKUP($B6,correlation!$A$2:$B$16,2,FALSE),1)) | H6: =IF($E6="","",IFERROR(VLOOKUP($E6,correlation!$D$2:$E$8,2,FALSE),1)) | I6: =ISNUMBER($F6) | J6: =AND($G6=1,$H6=1,$I6) | K6: =IF(mos_metrics!G5="","",mos_metrics!G5) | L6: =AND($J6,ISNUMBER(K6),correlation!$I$26=1) | M6: =IF(L6,$F6,"") | N6: =IF(L6,K6*correlation!$J$26,"") | O6: =IF(AND(L6,ISNUMBER(correlation!$F$26)),N6*correlation!$F$26+correlation!$G$26,"") | P6: =IF(AND(L6,ISNUMBER(O6)),(M6-O6)^2,"") | Q6: =IF(L6,1+SUMPRODUCT(--(calc!$L$3:$L$306=TRUE),--(calc!$M$3:$M$306>M6))+(SUMPRODUCT(--(calc!$L$3:$L$306=TRUE),--(calc!$M$3:$M$306=M6))-1)/2,"") | R6: =IF(L6,1+SUMPRODUCT(--(calc!$L$3:$L$306=TRUE),--(calc!$N$3:$N$306>N6))+(SUMPRODUCT(--(calc!$L$3:$L$306=TRUE),--(calc!$N$3:$N$306=N6))-1)/2,"") | S6: =IF(L6,SUMPRODUCT(--(calc!$L$3:$L$306=TRUE),--(ROW(calc!$L$3:$L$306)>ROW(L6)),--(((calc!$Q$3:$Q$306>Q6)*(calc!$R$3:$R$306>R6)+(calc!$Q$3:$Q$306<Q6)*(calc!$R$3:$R$306<R6))>0))-SUMPRODUCT(--(calc!$L$3:$L$306=TRUE),--(ROW(calc!$L$3:$L$306)>ROW(L6)),--(((calc!$Q$3:$Q$306>Q6)*(calc!$R$3:$R$306<R6)+(calc!$Q$3:$Q$306<Q6)*(calc!$R$3:$R$306>R6))>0)),0) | T6: =IF(mos_metrics!H5="","",mos_metrics!H5) | U6: =AND($J6,ISNUMBER(T6),correlation!$I$27=1) | V6: =IF(U6,$F6,"") | W6: =IF(U6,T6*correlation!$J$27,"") | X6: =IF(AND(U6,ISNUMBER(correlation!$F$27)),W6*correlation!$F$27+correlation!$G$27,"") | Y6: =IF(AND(U6,ISNUMBER(X6)),(V6-X6)^2,"") | Z6: =IF(U6,1+SUMPRODUCT(--(calc!$U$3:$U$306=TRUE),--(calc!$V$3:$V$306>V6))+(SUMPRODUCT(--(calc!$U$3:$U$306=TRUE),--(calc!$V$3:$V$306=V6))-1)/2,"") | AA6: =IF(U6,1+SUMPRODUCT(--(calc!$U$3:$U$306=TRUE),--(calc!$W$3:$W$306>W6))+(SUMPRODUCT(--(calc!$U$3:$U$306=TRUE),--(calc!$W$3:$W$306=W6))-1)/2,"") | AB6: =IF(U6,SUMPRODUCT(--(calc!$U$3:$U$306=TRUE),--(ROW(calc!$U$3:$U$306)>ROW(U6)),--(((calc!$Z$3:$Z$306>Z6)*(calc!$AA$3:$AA$306>AA6)+(calc!$Z$3:$Z$306<Z6)*(calc!$AA$3:$AA$306<AA6))>0))-SUMPRODUCT(--(calc!$U$3:$U$306=TRUE),--(ROW(calc!$U$3:$U$306)>ROW(U6)),--(((calc!$Z$3:$Z$306>Z6)*(calc!$AA$3:$AA$306<AA6)+(calc!$Z$3:$Z$306<Z6)*(calc!$AA$3:$AA$306>AA6))>0)),0) | AC6: =IF(mos_metrics!I5="","",mos_metrics!I5) | AD6: =AND($J6,ISNUMBER(AC6),correlation!$I$28=1) | AE6: =IF(AD6,$F6,"") | AF6: =IF(AD6,AC6*correlation!$J$28,"") | AG6: =IF(AND(AD6,ISNUMBER(correlation!$F$28)),AF6*correlation!$F$28+correlation!$G$28,"") | AH6: =IF(AND(AD6,ISNUMBER(AG6)),(AE6-AG6)^2,"") | AI6: =IF(AD6,1+SUMPRODUCT(--(calc!$AD$3:$AD$306=TRUE),--(calc!$AE$3:$AE$306>AE6))+(SUMPRODUCT(--(calc!$AD$3:$AD$306=TRUE),--(calc!$AE$3:$AE$306=AE6))-1)/2,"") | AJ6: =IF(AD6,1+SUMPRODUCT(--(calc!$AD$3:$AD$306=TRUE),--(calc!$AF$3:$AF$306>AF6))+(SUMPRODUCT(--(calc!$AD$3:$AD$306=TRUE),--(calc!$AF$3:$AF$306=AF6))-1)/2,"") | AK6: =IF(AD6,SUMPRODUCT(--(calc!$AD$3:$AD$306=TRUE),--(ROW(calc!$AD$3:$AD$306)>ROW(AD6)),--(((calc!$AI$3:$AI$306>AI6)*(calc!$AJ$3:$AJ$306>AJ6)+(calc!$AI$3:$AI$306<AI6)*(calc!$AJ$3:$AJ$306<AJ6))>0))-SUMPRODUCT(--(calc!$AD$3:$AD$306=TRUE),--(ROW(calc!$AD$3:$AD$306)>ROW(AD6)),--(((calc!$AI$3:$AI$306>AI6)*(calc!$AJ$3:$AJ$306<AJ6)+(calc!$AI$3:$AI$306<AI6)*(calc!$AJ$3:$AJ$306>AJ6))>0)),0) | AL6: =IF(mos_metrics!J5="","",mos_metrics!J5) | AM6: =AND($J6,ISNUMBER(AL6),correlation!$I$29=1) | AN6: =IF(AM6,$F6,"") | AO6: =IF(AM6,AL6*correlation!$J$29,"") | AP6: =IF(AND(AM6,ISNUMBER(correlation!$F$29)),AO6*correlation!$F$29+correlation!$G$29,"") | AQ6: =IF(AND(AM6,ISNUMBER(AP6)),(AN6-AP6)^2,"") | AR6: =IF(AM6,1+SUMPRODUCT(--(calc!$AM$3:$AM$306=TRUE),--(calc!$AN$3:$AN$306>AN6))+(SUMPRODUCT(--(calc!$AM$3:$AM$306=TRUE),--(calc!$AN$3:$AN$306=AN6))-1)/2,"") | AS6: =IF(AM6,1+SUMPRODUCT(--(calc!$AM$3:$AM$306=TRUE),--(calc!$AO$3:$AO$306>AO6))+(SUMPRODUCT(--(calc!$AM$3:$AM$306=TRUE),--(calc!$AO$3:$AO$306=AO6))-1)/2,"") | AT6: =IF(AM6,SUMPRODUCT(--(calc!$AM$3:$AM$306=TRUE),--(ROW(calc!$AM$3:$AM$306)>ROW(AM6)),--(((calc!$AR$3:$AR$306>AR6)*(calc!$AS$3:$AS$306>AS6)+(calc!$AR$3:$AR$306<AR6)*(calc!$AS$3:$AS$306<AS6))>0))-SUMPRODUCT(--(calc!$AM$3:$AM$306=TRUE),--(ROW(calc!$AM$3:$AM$306)>ROW(AM6)),--(((calc!$AR$3:$AR$306>AR6)*(calc!$AS$3:$AS$306<AS6)+(calc!$AR$3:$AR$306<AR6)*(calc!$AS$3:$AS$306>AS6))>0)),0) | AU6: =IF(mos_metrics!K5="","",mos_metrics!K5) | AV6: =AND($J6,ISNUMBER(AU6),correlation!$I$30=1) | AW6: =IF(AV6,$F6,"") | AX6: =IF(AV6,AU6*correlation!$J$30,"") | AY6: =IF(AND(AV6,ISNUMBER(correlation!$F$30)),AX6*correlation!$F$30+correlation!$G$30,"") | AZ6: =IF(AND(AV6,ISNUMBER(AY6)),(AW6-AY6)^2,"") | BA6: =IF(AV6,1+SUMPRODUCT(--(calc!$AV$3:$AV$306=TRUE),--(calc!$AW$3:$AW$306>AW6))+(SUMPRODUCT(--(calc!$AV$3:$AV$306=TRUE),--(calc!$AW$3:$AW$306=AW6))-1)/2,"") | BB6: =IF(AV6,1+SUMPRODUCT(--(calc!$AV$3:$AV$306=TRUE),--(calc!$AX$3:$AX$306>AX6))+(SUMPRODUCT(--(calc!$AV$3:$AV$306=TRUE),--(calc!$AX$3:$AX$306=AX6))-1)/2,"") | BC6: =IF(AV6,SUMPRODUCT(--(calc!$AV$3:$AV$306=TRUE),--(ROW(calc!$AV$3:$AV$306)>ROW(AV6)),--(((calc!$BA$3:$BA$306>BA6)*(calc!$BB$3:$BB$306>BB6)+(calc!$BA$3:$BA$306<BA6)*(calc!$BB$3:$BB$306<BB6))>0))-SUMPRODUCT(--(calc!$AV$3:$AV$306=TRUE),--(ROW(calc!$AV$3:$AV$306)>ROW(AV6)),--(((calc!$BA$3:$BA$306>BA6)*(calc!$BB$3:$BB$306<BB6)+(calc!$BA$3:$BA$306<BA6)*(calc!$BB$3:$BB$306>BB6))>0)),0) | BD6: =IF(mos_metrics!L5="","",mos_metrics!L5) | BE6: =AND($J6,ISNUMBER(BD6),correlation!$I$31=1) | BF6: =IF(BE6,$F6,"") | BG6: =IF(BE6,BD6*correlation!$J$31,"") | BH6: =IF(AND(BE6,ISNUMBER(correlation!$F$31)),BG6*correlation!$F$31+correlation!$G$31,"") | BI6: =IF(AND(BE6,ISNUMBER(BH6)),(BF6-BH6)^2,"") | BJ6: =IF(BE6,1+SUMPRODUCT(--(calc!$BE$3:$BE$306=TRUE),--(calc!$BF$3:$BF$306>BF6))+(SUMPRODUCT(--(calc!$BE$3:$BE$306=TRUE),--(calc!$BF$3:$BF$306=BF6))-1)/2,"") | BK6: =IF(BE6,1+SUMPRODUCT(--(calc!$BE$3:$BE$306=TRUE),--(calc!$BG$3:$BG$306>BG6))+(SUMPRODUCT(--(calc!$BE$3:$BE$306=TRUE),--(calc!$BG$3:$BG$306=BG6))-1)/2,"") | BL6: =IF(BE6,SUMPRODUCT(--(calc!$BE$3:$BE$306=TRUE),--(ROW(calc!$BE$3:$BE$306)>ROW(BE6)),--(((calc!$BJ$3:$BJ$306>BJ6)*(calc!$BK$3:$BK$306>BK6)+(calc!$BJ$3:$BJ$306<BJ6)*(calc!$BK$3:$BK$306<BK6))>0))-SUMPRODUCT(--(calc!$BE$3:$BE$306=TRUE),--(ROW(calc!$BE$3:$BE$306)>ROW(BE6)),--(((calc!$BJ$3:$BJ$306>BJ6)*(calc!$BK$3:$BK$306<BK6)+(calc!$BJ$3:$BJ$306<BJ6)*(calc!$BK$3:$BK$306>BK6))>0)),0) | BM6: =IF(mos_metrics!M5="","",mos_metrics!M5) | BN6: =AND($J6,ISNUMBER(BM6),correlation!$I$32=1) | BO6: =IF(BN6,$F6,"") | BP6: =IF(BN6,BM6*correlation!$J$32,"") | BQ6: =IF(AND(BN6,ISNUMBER(correlation!$F$32)),BP6*correlation!$F$32+correlation!$G$32,"") | BR6: =IF(AND(BN6,ISNUMBER(BQ6)),(BO6-BQ6)^2,"") | BS6: =IF(BN6,1+SUMPRODUCT(--(calc!$BN$3:$BN$306=TRUE),--(calc!$BO$3:$BO$306>BO6))+(SUMPRODUCT(--(calc!$BN$3:$BN$306=TRUE),--(calc!$BO$3:$BO$306=BO6))-1)/2,"") | BT6: =IF(BN6,1+SUMPRODUCT(--(calc!$BN$3:$BN$306=TRUE),--(calc!$BP$3:$BP$306>BP6))+(SUMPRODUCT(--(calc!$BN$3:$BN$306=TRUE),--(calc!$BP$3:$BP$306=BP6))-1)/2,"") | BU6: =IF(BN6,SUMPRODUCT(--(calc!$BN$3:$BN$306=TRUE),--(ROW(calc!$BN$3:$BN$306)>ROW(BN6)),--(((calc!$BS$3:$BS$306>BS6)*(calc!$BT$3:$BT$306>BT6)+(calc!$BS$3:$BS$306<BS6)*(calc!$BT$3:$BT$306<BT6))>0))-SUMPRODUCT(--(calc!$BN$3:$BN$306=TRUE),--(ROW(calc!$BN$3:$BN$306)>ROW(BN6)),--(((calc!$BS$3:$BS$306>BS6)*(calc!$BT$3:$BT$306<BT6)+(calc!$BS$3:$BS$306<BS6)*(calc!$BT$3:$BT$306>BT6))>0)),0)
A7: =mos_metrics!A6 | B7: =mos_metrics!B6 | C7: =mos_metrics!C6 | D7: =mos_metrics!D6 | E7: =mos_metrics!E6 | F7: =mos_metrics!F6 | G7: =IF($B7="","",IFERROR(VLOOKUP($B7,correlation!$A$2:$B$16,2,FALSE),1)) | H7: =IF($E7="","",IFERROR(VLOOKUP($E7,correlation!$D$2:$E$8,2,FALSE),1)) | I7: =ISNUMBER($F7) | J7: =AND($G7=1,$H7=1,$I7) | K7: =IF(mos_metrics!G6="","",mos_metrics!G6) | L7: =AND($J7,ISNUMBER(K7),correlation!$I$26=1) | M7: =IF(L7,$F7,"") | N7: =IF(L7,K7*correlation!$J$26,"") | O7: =IF(AND(L7,ISNUMBER(correlation!$F$26)),N7*correlation!$F$26+correlation!$G$26,"") | P7: =IF(AND(L7,ISNUMBER(O7)),(M7-O7)^2,"") | Q7: =IF(L7,1+SUMPRODUCT(--(calc!$L$3:$L$306=TRUE),--(calc!$M$3:$M$306>M7))+(SUMPRODUCT(--(calc!$L$3:$L$306=TRUE),--(calc!$M$3:$M$306=M7))-1)/2,"") | R7: =IF(L7,1+SUMPRODUCT(--(calc!$L$3:$L$306=TRUE),--(calc!$N$3:$N$306>N7))+(SUMPRODUCT(--(calc!$L$3:$L$306=TRUE),--(calc!$N$3:$N$306=N7))-1)/2,"") | S7: =IF(L7,SUMPRODUCT(--(calc!$L$3:$L$306=TRUE),--(ROW(calc!$L$3:$L$306)>ROW(L7)),--(((calc!$Q$3:$Q$306>Q7)*(calc!$R$3:$R$306>R7)+(calc!$Q$3:$Q$306<Q7)*(calc!$R$3:$R$306<R7))>0))-SUMPRODUCT(--(calc!$L$3:$L$306=TRUE),--(ROW(calc!$L$3:$L$306)>ROW(L7)),--(((calc!$Q$3:$Q$306>Q7)*(calc!$R$3:$R$306<R7)+(calc!$Q$3:$Q$306<Q7)*(calc!$R$3:$R$306>R7))>0)),0) | T7: =IF(mos_metrics!H6="","",mos_metrics!H6) | U7: =AND($J7,ISNUMBER(T7),correlation!$I$27=1) | V7: =IF(U7,$F7,"") | W7: =IF(U7,T7*correlation!$J$27,"") | X7: =IF(AND(U7,ISNUMBER(correlation!$F$27)),W7*correlation!$F$27+correlation!$G$27,"") | Y7: =IF(AND(U7,ISNUMBER(X7)),(V7-X7)^2,"") | Z7: =IF(U7,1+SUMPRODUCT(--(calc!$U$3:$U$306=TRUE),--(calc!$V$3:$V$306>V7))+(SUMPRODUCT(--(calc!$U$3:$U$306=TRUE),--(calc!$V$3:$V$306=V7))-1)/2,"") | AA7: =IF(U7,1+SUMPRODUCT(--(calc!$U$3:$U$306=TRUE),--(calc!$W$3:$W$306>W7))+(SUMPRODUCT(--(calc!$U$3:$U$306=TRUE),--(calc!$W$3:$W$306=W7))-1)/2,"") | AB7: =IF(U7,SUMPRODUCT(--(calc!$U$3:$U$306=TRUE),--(ROW(calc!$U$3:$U$306)>ROW(U7)),--(((calc!$Z$3:$Z$306>Z7)*(calc!$AA$3:$AA$306>AA7)+(calc!$Z$3:$Z$306<Z7)*(calc!$AA$3:$AA$306<AA7))>0))-SUMPRODUCT(--(calc!$U$3:$U$306=TRUE),--(ROW(calc!$U$3:$U$306)>ROW(U7)),--(((calc!$Z$3:$Z$306>Z7)*(calc!$AA$3:$AA$306<AA7)+(calc!$Z$3:$Z$306<Z7)*(calc!$AA$3:$AA$306>AA7))>0)),0) | AC7: =IF(mos_metrics!I6="","",mos_metrics!I6) | AD7: =AND($J7,ISNUMBER(AC7),correlation!$I$28=1) | AE7: =IF(AD7,$F7,"") | AF7: =IF(AD7,AC7*correlation!$J$28,"") | AG7: =IF(AND(AD7,ISNUMBER(correlation!$F$28)),AF7*correlation!$F$28+correlation!$G$28,"") | AH7: =IF(AND(AD7,ISNUMBER(AG7)),(AE7-AG7)^2,"") | AI7: =IF(AD7,1+SUMPRODUCT(--(calc!$AD$3:$AD$306=TRUE),--(calc!$AE$3:$AE$306>AE7))+(SUMPRODUCT(--(calc!$AD$3:$AD$306=TRUE),--(calc!$AE$3:$AE$306=AE7))-1)/2,"") | AJ7: =IF(AD7,1+SUMPRODUCT(--(calc!$AD$3:$AD$306=TRUE),--(calc!$AF$3:$AF$306>AF7))+(SUMPRODUCT(--(calc!$AD$3:$AD$306=TRUE),--(calc!$AF$3:$AF$306=AF7))-1)/2,"") | AK7: =IF(AD7,SUMPRODUCT(--(calc!$AD$3:$AD$306=TRUE),--(ROW(calc!$AD$3:$AD$306)>ROW(AD7)),--(((calc!$AI$3:$AI$306>AI7)*(calc!$AJ$3:$AJ$306>AJ7)+(calc!$AI$3:$AI$306<AI7)*(calc!$AJ$3:$AJ$306<AJ7))>0))-SUMPRODUCT(--(calc!$AD$3:$AD$306=TRUE),--(ROW(calc!$AD$3:$AD$306)>ROW(AD7)),--(((calc!$AI$3:$AI$306>AI7)*(calc!$AJ$3:$AJ$306<AJ7)+(calc!$AI$3:$AI$306<AI7)*(calc!$AJ$3:$AJ$306>AJ7))>0)),0) | AL7: =IF(mos_metrics!J6="","",mos_metrics!J6) | AM7: =AND($J7,ISNUMBER(AL7),correlation!$I$29=1) | AN7: =IF(AM7,$F7,"") | AO7: =IF(AM7,AL7*correlation!$J$29,"") | AP7: =IF(AND(AM7,ISNUMBER(correlation!$F$29)),AO7*correlation!$F$29+correlation!$G$29,"") | AQ7: =IF(AND(AM7,ISNUMBER(AP7)),(AN7-AP7)^2,"") | AR7: =IF(AM7,1+SUMPRODUCT(--(calc!$AM$3:$AM$306=TRUE),--(calc!$AN$3:$AN$306>AN7))+(SUMPRODUCT(--(calc!$AM$3:$AM$306=TRUE),--(calc!$AN$3:$AN$306=AN7))-1)/2,"") | AS7: =IF(AM7,1+SUMPRODUCT(--(calc!$AM$3:$AM$306=TRUE),--(calc!$AO$3:$AO$306>AO7))+(SUMPRODUCT(--(calc!$AM$3:$AM$306=TRUE),--(calc!$AO$3:$AO$306=AO7))-1)/2,"") | AT7: =IF(AM7,SUMPRODUCT(--(calc!$AM$3:$AM$306=TRUE),--(ROW(calc!$AM$3:$AM$306)>ROW(AM7)),--(((calc!$AR$3:$AR$306>AR7)*(calc!$AS$3:$AS$306>AS7)+(calc!$AR$3:$AR$306<AR7)*(calc!$AS$3:$AS$306<AS7))>0))-SUMPRODUCT(--(calc!$AM$3:$AM$306=TRUE),--(ROW(calc!$AM$3:$AM$306)>ROW(AM7)),--(((calc!$AR$3:$AR$306>AR7)*(calc!$AS$3:$AS$306<AS7)+(calc!$AR$3:$AR$306<AR7)*(calc!$AS$3:$AS$306>AS7))>0)),0) | AU7: =IF(mos_metrics!K6="","",mos_metrics!K6) | AV7: =AND($J7,ISNUMBER(AU7),correlation!$I$30=1) | AW7: =IF(AV7,$F7,"") | AX7: =IF(AV7,AU7*correlation!$J$30,"") | AY7: =IF(AND(AV7,ISNUMBER(correlation!$F$30)),AX7*correlation!$F$30+correlation!$G$30,"") | AZ7: =IF(AND(AV7,ISNUMBER(AY7)),(AW7-AY7)^2,"") | BA7: =IF(AV7,1+SUMPRODUCT(--(calc!$AV$3:$AV$306=TRUE),--(calc!$AW$3:$AW$306>AW7))+(SUMPRODUCT(--(calc!$AV$3:$AV$306=TRUE),--(calc!$AW$3:$AW$306=AW7))-1)/2,"") | BB7: =IF(AV7,1+SUMPRODUCT(--(calc!$AV$3:$AV$306=TRUE),--(calc!$AX$3:$AX$306>AX7))+(SUMPRODUCT(--(calc!$AV$3:$AV$306=TRUE),--(calc!$AX$3:$AX$306=AX7))-1)/2,"") | BC7: =IF(AV7,SUMPRODUCT(--(calc!$AV$3:$AV$306=TRUE),--(ROW(calc!$AV$3:$AV$306)>ROW(AV7)),--(((calc!$BA$3:$BA$306>BA7)*(calc!$BB$3:$BB$306>BB7)+(calc!$BA$3:$BA$306<BA7)*(calc!$BB$3:$BB$306<BB7))>0))-SUMPRODUCT(--(calc!$AV$3:$AV$306=TRUE),--(ROW(calc!$AV$3:$AV$306)>ROW(AV7)),--(((calc!$BA$3:$BA$306>BA7)*(calc!$BB$3:$BB$306<BB7)+(calc!$BA$3:$BA$306<BA7)*(calc!$BB$3:$BB$306>BB7))>0)),0) | BD7: =IF(mos_metrics!L6="","",mos_metrics!L6) | BE7: =AND($J7,ISNUMBER(BD7),correlation!$I$31=1) | BF7: =IF(BE7,$F7,"") | BG7: =IF(BE7,BD7*correlation!$J$31,"") | BH7: =IF(AND(BE7,ISNUMBER(correlation!$F$31)),BG7*correlation!$F$31+correlation!$G$31,"") | BI7: =IF(AND(BE7,ISNUMBER(BH7)),(BF7-BH7)^2,"") | BJ7: =IF(BE7,1+SUMPRODUCT(--(calc!$BE$3:$BE$306=TRUE),--(calc!$BF$3:$BF$306>BF7))+(SUMPRODUCT(--(calc!$BE$3:$BE$306=TRUE),--(calc!$BF$3:$BF$306=BF7))-1)/2,"") | BK7: =IF(BE7,1+SUMPRODUCT(--(calc!$BE$3:$BE$306=TRUE),--(calc!$BG$3:$BG$306>BG7))+(SUMPRODUCT(--(calc!$BE$3:$BE$306=TRUE),--(calc!$BG$3:$BG$306=BG7))-1)/2,"") | BL7: =IF(BE7,SUMPRODUCT(--(calc!$BE$3:$BE$306=TRUE),--(ROW(calc!$BE$3:$BE$306)>ROW(BE7)),--(((calc!$BJ$3:$BJ$306>BJ7)*(calc!$BK$3:$BK$306>BK7)+(calc!$BJ$3:$BJ$306<BJ7)*(calc!$BK$3:$BK$306<BK7))>0))-SUMPRODUCT(--(calc!$BE$3:$BE$306=TRUE),--(ROW(calc!$BE$3:$BE$306)>ROW(BE7)),--(((calc!$BJ$3:$BJ$306>BJ7)*(calc!$BK$3:$BK$306<BK7)+(calc!$BJ$3:$BJ$306<BJ7)*(calc!$BK$3:$BK$306>BK7))>0)),0) | BM7: =IF(mos_metrics!M6="","",mos_metrics!M6) | BN7: =AND($J7,ISNUMBER(BM7),correlation!$I$32=1) | BO7: =IF(BN7,$F7,"") | BP7: =IF(BN7,BM7*correlation!$J$32,"") | BQ7: =IF(AND(BN7,ISNUMBER(correlation!$F$32)),BP7*correlation!$F$32+correlation!$G$32,"") | BR7: =IF(AND(BN7,ISNUMBER(BQ7)),(BO7-BQ7)^2,"") | BS7: =IF(BN7,1+SUMPRODUCT(--(calc!$BN$3:$BN$306=TRUE),--(calc!$BO$3:$BO$306>BO7))+(SUMPRODUCT(--(calc!$BN$3:$BN$306=TRUE),--(calc!$BO$3:$BO$306=BO7))-1)/2,"") | BT7: =IF(BN7,1+SUMPRODUCT(--(calc!$BN$3:$BN$306=TRUE),--(calc!$BP$3:$BP$306>BP7))+(SUMPRODUCT(--(calc!$BN$3:$BN$306=TRUE),--(calc!$BP$3:$BP$306=BP7))-1)/2,"") | BU7: =IF(BN7,SUMPRODUCT(--(calc!$BN$3:$BN$306=TRUE),--(ROW(calc!$BN$3:$BN$306)>ROW(BN7)),--(((calc!$BS$3:$BS$306>BS7)*(calc!$BT$3:$BT$306>BT7)+(calc!$BS$3:$BS$306<BS7)*(calc!$BT$3:$BT$306<BT7))>0))-SUMPRODUCT(--(calc!$BN$3:$BN$306=TRUE),--(ROW(calc!$BN$3:$BN$306)>ROW(BN7)),--(((calc!$BS$3:$BS$306>BS7)*(calc!$BT$3:$BT$306<BT7)+(calc!$BS$3:$BS$306<BS7)*(calc!$BT$3:$BT$306>BT7))>0)),0)
A8: =mos_metrics!A7 | B8: =mos_metrics!B7 | C8: =mos_metrics!C7 | D8: =mos_metrics!D7 | E8: =mos_metrics!E7 | F8: =mos_metrics!F7 | G8: =IF($B8="","",IFERROR(VLOOKUP($B8,correlation!$A$2:$B$16,2,FALSE),1)) | H8: =IF($E8="","",IFERROR(VLOOKUP($E8,correlation!$D$2:$E$8,2,FALSE),1)) | I8: =ISNUMBER($F8) | J8: =AND($G8=1,$H8=1,$I8) | K8: =IF(mos_metrics!G7="","",mos_metrics!G7) | L8: =AND($J8,ISNUMBER(K8),correlation!$I$26=1) | M8: =IF(L8,$F8,"") | N8: =IF(L8,K8*correlation!$J$26,"") | O8: =IF(AND(L8,ISNUMBER(correlation!$F$26)),N8*correlation!$F$26+correlation!$G$26,"") | P8: =IF(AND(L8,ISNUMBER(O8)),(M8-O8)^2,"") | Q8: =IF(L8,1+SUMPRODUCT(--(calc!$L$3:$L$306=TRUE),--(calc!$M$3:$M$306>M8))+(SUMPRODUCT(--(calc!$L$3:$L$306=TRUE),--(calc!$M$3:$M$306=M8))-1)/2,"") | R8: =IF(L8,1+SUMPRODUCT(--(calc!$L$3:$L$306=TRUE),--(calc!$N$3:$N$306>N8))+(SUMPRODUCT(--(calc!$L$3:$L$306=TRUE),--(calc!$N$3:$N$306=N8))-1)/2,"") | S8: =IF(L8,SUMPRODUCT(--(calc!$L$3:$L$306=TRUE),--(ROW(calc!$L$3:$L$306)>ROW(L8)),--(((calc!$Q$3:$Q$306>Q8)*(calc!$R$3:$R$306>R8)+(calc!$Q$3:$Q$306<Q8)*(calc!$R$3:$R$306<R8))>0))-SUMPRODUCT(--(calc!$L$3:$L$306=TRUE),--(ROW(calc!$L$3:$L$306)>ROW(L8)),--(((calc!$Q$3:$Q$306>Q8)*(calc!$R$3:$R$306<R8)+(calc!$Q$3:$Q$306<Q8)*(calc!$R$3:$R$306>R8))>0)),0) | T8: =IF(mos_metrics!H7="","",mos_metrics!H7) | U8: =AND($J8,ISNUMBER(T8),correlation!$I$27=1) | V8: =IF(U8,$F8,"") | W8: =IF(U8,T8*correlation!$J$27,"") | X8: =IF(AND(U8,ISNUMBER(correlation!$F$27)),W8*correlation!$F$27+correlation!$G$27,"") | Y8: =IF(AND(U8,ISNUMBER(X8)),(V8-X8)^2,"") | Z8: =IF(U8,1+SUMPRODUCT(--(calc!$U$3:$U$306=TRUE),--(calc!$V$3:$V$306>V8))+(SUMPRODUCT(--(calc!$U$3:$U$306=TRUE),--(calc!$V$3:$V$306=V8))-1)/2,"") | AA8: =IF(U8,1+SUMPRODUCT(--(calc!$U$3:$U$306=TRUE),--(calc!$W$3:$W$306>W8))+(SUMPRODUCT(--(calc!$U$3:$U$306=TRUE),--(calc!$W$3:$W$306=W8))-1)/2,"") | AB8: =IF(U8,SUMPRODUCT(--(calc!$U$3:$U$306=TRUE),--(ROW(calc!$U$3:$U$306)>ROW(U8)),--(((calc!$Z$3:$Z$306>Z8)*(calc!$AA$3:$AA$306>AA8)+(calc!$Z$3:$Z$306<Z8)*(calc!$AA$3:$AA$306<AA8))>0))-SUMPRODUCT(--(calc!$U$3:$U$306=TRUE),--(ROW(calc!$U$3:$U$306)>ROW(U8)),--(((calc!$Z$3:$Z$306>Z8)*(calc!$AA$3:$AA$306<AA8)+(calc!$Z$3:$Z$306<Z8)*(calc!$AA$3:$AA$306>AA8))>0)),0) | AC8: =IF(mos_metrics!I7="","",mos_metrics!I7) | AD8: =AND($J8,ISNUMBER(AC8),correlation!$I$28=1) | AE8: =IF(AD8,$F8,"") | AF8: =IF(AD8,AC8*correlation!$J$28,"") | AG8: =IF(AND(AD8,ISNUMBER(correlation!$F$28)),AF8*correlation!$F$28+correlation!$G$28,"") | AH8: =IF(AND(AD8,ISNUMBER(AG8)),(AE8-AG8)^2,"") | AI8: =IF(AD8,1+SUMPRODUCT(--(calc!$AD$3:$AD$306=TRUE),--(calc!$AE$3:$AE$306>AE8))+(SUMPRODUCT(--(calc!$AD$3:$AD$306=TRUE),--(calc!$AE$3:$AE$306=AE8))-1)/2,"") | AJ8: =IF(AD8,1+SUMPRODUCT(--(calc!$AD$3:$AD$306=TRUE),--(calc!$AF$3:$AF$306>AF8))+(SUMPRODUCT(--(calc!$AD$3:$AD$306=TRUE),--(calc!$AF$3:$AF$306=AF8))-1)/2,"") | AK8: =IF(AD8,SUMPRODUCT(--(calc!$AD$3:$AD$306=TRUE),--(ROW(calc!$AD$3:$AD$306)>ROW(AD8)),--(((calc!$AI$3:$AI$306>AI8)*(calc!$AJ$3:$AJ$306>AJ8)+(calc!$AI$3:$AI$306<AI8)*(calc!$AJ$3:$AJ$306<AJ8))>0))-SUMPRODUCT(--(calc!$AD$3:$AD$306=TRUE),--(ROW(calc!$AD$3:$AD$306)>ROW(AD8)),--(((calc!$AI$3:$AI$306>AI8)*(calc!$AJ$3:$AJ$306<AJ8)+(calc!$AI$3:$AI$306<AI8)*(calc!$AJ$3:$AJ$306>AJ8))>0)),0) | AL8: =IF(mos_metrics!J7="","",mos_metrics!J7) | AM8: =AND($J8,ISNUMBER(AL8),correlation!$I$29=1) | AN8: =IF(AM8,$F8,"") | AO8: =IF(AM8,AL8*correlation!$J$29,"") | AP8: =IF(AND(AM8,ISNUMBER(correlation!$F$29)),AO8*correlation!$F$29+correlation!$G$29,"") | AQ8: =IF(AND(AM8,ISNUMBER(AP8)),(AN8-AP8)^2,"") | AR8: =IF(AM8,1+SUMPRODUCT(--(calc!$AM$3:$AM$306=TRUE),--(calc!$AN$3:$AN$306>AN8))+(SUMPRODUCT(--(calc!$AM$3:$AM$306=TRUE),--(calc!$AN$3:$AN$306=AN8))-1)/2,"") | AS8: =IF(AM8,1+SUMPRODUCT(--(calc!$AM$3:$AM$306=TRUE),--(calc!$AO$3:$AO$306>AO8))+(SUMPRODUCT(--(calc!$AM$3:$AM$306=TRUE),--(calc!$AO$3:$AO$306=AO8))-1)/2,"") | AT8: =IF(AM8,SUMPRODUCT(--(calc!$AM$3:$AM$306=TRUE),--(ROW(calc!$AM$3:$AM$306)>ROW(AM8)),--(((calc!$AR$3:$AR$306>AR8)*(calc!$AS$3:$AS$306>AS8)+(calc!$AR$3:$AR$306<AR8)*(calc!$AS$3:$AS$306<AS8))>0))-SUMPRODUCT(--(calc!$AM$3:$AM$306=TRUE),--(ROW(calc!$AM$3:$AM$306)>ROW(AM8)),--(((calc!$AR$3:$AR$306>AR8)*(calc!$AS$3:$AS$306<AS8)+(calc!$AR$3:$AR$306<AR8)*(calc!$AS$3:$AS$306>AS8))>0)),0) | AU8: =IF(mos_metrics!K7="","",mos_metrics!K7) | AV8: =AND($J8,ISNUMBER(AU8),correlation!$I$30=1) | AW8: =IF(AV8,$F8,"") | AX8: =IF(AV8,AU8*correlation!$J$30,"") | AY8: =IF(AND(AV8,ISNUMBER(correlation!$F$30)),AX8*correlation!$F$30+correlation!$G$30,"") | AZ8: =IF(AND(AV8,ISNUMBER(AY8)),(AW8-AY8)^2,"") | BA8: =IF(AV8,1+SUMPRODUCT(--(calc!$AV$3:$AV$306=TRUE),--(calc!$AW$3:$AW$306>AW8))+(SUMPRODUCT(--(calc!$AV$3:$AV$306=TRUE),--(calc!$AW$3:$AW$306=AW8))-1)/2,"") | BB8: =IF(AV8,1+SUMPRODUCT(--(calc!$AV$3:$AV$306=TRUE),--(calc!$AX$3:$AX$306>AX8))+(SUMPRODUCT(--(calc!$AV$3:$AV$306=TRUE),--(calc!$AX$3:$AX$306=AX8))-1)/2,"") | BC8: =IF(AV8,SUMPRODUCT(--(calc!$AV$3:$AV$306=TRUE),--(ROW(calc!$AV$3:$AV$306)>ROW(AV8)),--(((calc!$BA$3:$BA$306>BA8)*(calc!$BB$3:$BB$306>BB8)+(calc!$BA$3:$BA$306<BA8)*(calc!$BB$3:$BB$306<BB8))>0))-SUMPRODUCT(--(calc!$AV$3:$AV$306=TRUE),--(ROW(calc!$AV$3:$AV$306)>ROW(AV8)),--(((calc!$BA$3:$BA$306>BA8)*(calc!$BB$3:$BB$306<BB8)+(calc!$BA$3:$BA$306<BA8)*(calc!$BB$3:$BB$306>BB8))>0)),0) | BD8: =IF(mos_metrics!L7="","",mos_metrics!L7) | BE8: =AND($J8,ISNUMBER(BD8),correlation!$I$31=1) | BF8: =IF(BE8,$F8,"") | BG8: =IF(BE8,BD8*correlation!$J$31,"") | BH8: =IF(AND(BE8,ISNUMBER(correlation!$F$31)),BG8*correlation!$F$31+correlation!$G$31,"") | BI8: =IF(AND(BE8,ISNUMBER(BH8)),(BF8-BH8)^2,"") | BJ8: =IF(BE8,1+SUMPRODUCT(--(calc!$BE$3:$BE$306=TRUE),--(calc!$BF$3:$BF$306>BF8))+(SUMPRODUCT(--(calc!$BE$3:$BE$306=TRUE),--(calc!$BF$3:$BF$306=BF8))-1)/2,"") | BK8: =IF(BE8,1+SUMPRODUCT(--(calc!$BE$3:$BE$306=TRUE),--(calc!$BG$3:$BG$306>BG8))+(SUMPRODUCT(--(calc!$BE$3:$BE$306=TRUE),--(calc!$BG$3:$BG$306=BG8))-1)/2,"") | BL8: =IF(BE8,SUMPRODUCT(--(calc!$BE$3:$BE$306=TRUE),--(ROW(calc!$BE$3:$BE$306)>ROW(BE8)),--(((calc!$BJ$3:$BJ$306>BJ8)*(calc!$BK$3:$BK$306>BK8)+(calc!$BJ$3:$BJ$306<BJ8)*(calc!$BK$3:$BK$306<BK8))>0))-SUMPRODUCT(--(calc!$BE$3:$BE$306=TRUE),--(ROW(calc!$BE$3:$BE$306)>ROW(BE8)),--(((calc!$BJ$3:$BJ$306>BJ8)*(calc!$BK$3:$BK$306<BK8)+(calc!$BJ$3:$BJ$306<BJ8)*(calc!$BK$3:$BK$306>BK8))>0)),0) | BM8: =IF(mos_metrics!M7="","",mos_metrics!M7) | BN8: =AND($J8,ISNUMBER(BM8),correlation!$I$32=1) | BO8: =IF(BN8,$F8,"") | BP8: =IF(BN8,BM8*correlation!$J$32,"") | BQ8: =IF(AND(BN8,ISNUMBER(correlation!$F$32)),BP8*correlation!$F$32+correlation!$G$32,"") | BR8: =IF(AND(BN8,ISNUMBER(BQ8)),(BO8-BQ8)^2,"") | BS8: =IF(BN8,1+SUMPRODUCT(--(calc!$BN$3:$BN$306=TRUE),--(calc!$BO$3:$BO$306>BO8))+(SUMPRODUCT(--(calc!$BN$3:$BN$306=TRUE),--(calc!$BO$3:$BO$306=BO8))-1)/2,"") | BT8: =IF(BN8,1+SUMPRODUCT(--(calc!$BN$3:$BN$306=TRUE),--(calc!$BP$3:$BP$306>BP8))+(SUMPRODUCT(--(calc!$BN$3:$BN$306=TRUE),--(calc!$BP$3:$BP$306=BP8))-1)/2,"") | BU8: =IF(BN8,SUMPRODUCT(--(calc!$BN$3:$BN$306=TRUE),--(ROW(calc!$BN$3:$BN$306)>ROW(BN8)),--(((calc!$BS$3:$BS$306>BS8)*(calc!$BT$3:$BT$306>BT8)+(calc!$BS$3:$BS$306<BS8)*(calc!$BT$3:$BT$306<BT8))>0))-SUMPRODUCT(--(calc!$BN$3:$BN$306=TRUE),--(ROW(calc!$BN$3:$BN$306)>ROW(BN8)),--(((calc!$BS$3:$BS$306>BS8)*(calc!$BT$3:$BT$306<BT8)+(calc!$BS$3:$BS$306<BS8)*(calc!$BT$3:$BT$306>BT8))>0)),0)
A9: =mos_metrics!A8 | B9: =mos_metrics!B8 | C9: =mos_metrics!C8 | D9: =mos_metrics!D8 | E9: =mos_metrics!E8 | F9: =mos_metrics!F8 | G9: =IF($B9="","",IFERROR(VLOOKUP($B9,correlation!$A$2:$B$16,2,FALSE),1)) | H9: =IF($E9="","",IFERROR(VLOOKUP($E9,correlation!$D$2:$E$8,2,FALSE),1)) | I9: =ISNUMBER($F9) | J9: =AND($G9=1,$H9=1,$I9) | K9: =IF(mos_metrics!G8="","",mos_metrics!G8) | L9: =AND($J9,ISNUMBER(K9),correlation!$I$26=1) | M9: =IF(L9,$F9,"") | N9: =IF(L9,K9*correlation!$J$26,"") | O9: =IF(AND(L9,ISNUMBER(correlation!$F$26)),N9*correlation!$F$26+correlation!$G$26,"") | P9: =IF(AND(L9,ISNUMBER(O9)),(M9-O9)^2,"") | Q9: =IF(L9,1+SUMPRODUCT(--(calc!$L$3:$L$306=TRUE),--(calc!$M$3:$M$306>M9))+(SUMPRODUCT(--(calc!$L$3:$L$306=TRUE),--(calc!$M$3:$M$306=M9))-1)/2,"") | R9: =IF(L9,1+SUMPRODUCT(--(calc!$L$3:$L$306=TRUE),--(calc!$N$3:$N$306>N9))+(SUMPRODUCT(--(calc!$L$3:$L$306=TRUE),--(calc!$N$3:$N$306=N9))-1)/2,"") | S9: =IF(L9,SUMPRODUCT(--(calc!$L$3:$L$306=TRUE),--(ROW(calc!$L$3:$L$306)>ROW(L9)),--(((calc!$Q$3:$Q$306>Q9)*(calc!$R$3:$R$306>R9)+(calc!$Q$3:$Q$306<Q9)*(calc!$R$3:$R$306<R9))>0))-SUMPRODUCT(--(calc!$L$3:$L$306=TRUE),--(ROW(calc!$L$3:$L$306)>ROW(L9)),--(((calc!$Q$3:$Q$306>Q9)*(calc!$R$3:$R$306<R9)+(calc!$Q$3:$Q$306<Q9)*(calc!$R$3:$R$306>R9))>0)),0) | T9: =IF(mos_metrics!H8="","",mos_metrics!H8) | U9: =AND($J9,ISNUMBER(T9),correlation!$I$27=1) | V9: =IF(U9,$F9,"") | W9: =IF(U9,T9*correlation!$J$27,"") | X9: =IF(AND(U9,ISNUMBER(correlation!$F$27)),W9*correlation!$F$27+correlation!$G$27,"") | Y9: =IF(AND(U9,ISNUMBER(X9)),(V9-X9)^2,"") | Z9: =IF(U9,1+SUMPRODUCT(--(calc!$U$3:$U$306=TRUE),--(calc!$V$3:$V$306>V9))+(SUMPRODUCT(--(calc!$U$3:$U$306=TRUE),--(calc!$V$3:$V$306=V9))-1)/2,"") | AA9: =IF(U9,1+SUMPRODUCT(--(calc!$U$3:$U$306=TRUE),--(calc!$W$3:$W$306>W9))+(SUMPRODUCT(--(calc!$U$3:$U$306=TRUE),--(calc!$W$3:$W$306=W9))-1)/2,"") | AB9: =IF(U9,SUMPRODUCT(--(calc!$U$3:$U$306=TRUE),--(ROW(calc!$U$3:$U$306)>ROW(U9)),--(((calc!$Z$3:$Z$306>Z9)*(calc!$AA$3:$AA$306>AA9)+(calc!$Z$3:$Z$306<Z9)*(calc!$AA$3:$AA$306<AA9))>0))-SUMPRODUCT(--(calc!$U$3:$U$306=TRUE),--(ROW(calc!$U$3:$U$306)>ROW(U9)),--(((calc!$Z$3:$Z$306>Z9)*(calc!$AA$3:$AA$306<AA9)+(calc!$Z$3:$Z$306<Z9)*(calc!$AA$3:$AA$306>AA9))>0)),0) | AC9: =IF(mos_metrics!I8="","",mos_metrics!I8) | AD9: =AND($J9,ISNUMBER(AC9),correlation!$I$28=1) | AE9: =IF(AD9,$F9,"") | AF9: =IF(AD9,AC9*correlation!$J$28,"") | AG9: =IF(AND(AD9,ISNUMBER(correlation!$F$28)),AF9*correlation!$F$28+correlation!$G$28,"") | AH9: =IF(AND(AD9,ISNUMBER(AG9)),(AE9-AG9)^2,"") | AI9: =IF(AD9,1+SUMPRODUCT(--(calc!$AD$3:$AD$306=TRUE),--(calc!$AE$3:$AE$306>AE9))+(SUMPRODUCT(--(calc!$AD$3:$AD$306=TRUE),--(calc!$AE$3:$AE$306=AE9))-1)/2,"") | AJ9: =IF(AD9,1+SUMPRODUCT(--(calc!$AD$3:$AD$306=TRUE),--(calc!$AF$3:$AF$306>AF9))+(SUMPRODUCT(--(calc!$AD$3:$AD$306=TRUE),--(calc!$AF$3:$AF$306=AF9))-1)/2,"") | AK9: =IF(AD9,SUMPRODUCT(--(calc!$AD$3:$AD$306=TRUE),--(ROW(calc!$AD$3:$AD$306)>ROW(AD9)),--(((calc!$AI$3:$AI$306>AI9)*(calc!$AJ$3:$AJ$306>AJ9)+(calc!$AI$3:$AI$306<AI9)*(calc!$AJ$3:$AJ$306<AJ9))>0))-SUMPRODUCT(--(calc!$AD$3:$AD$306=TRUE),--(ROW(calc!$AD$3:$AD$306)>ROW(AD9)),--(((calc!$AI$3:$AI$306>AI9)*(calc!$AJ$3:$AJ$306<AJ9)+(calc!$AI$3:$AI$306<AI9)*(calc!$AJ$3:$AJ$306>AJ9))>0)),0) | AL9: =IF(mos_metrics!J8="","",mos_metrics!J8) | AM9: =AND($J9,ISNUMBER(AL9),correlation!$I$29=1) | AN9: =IF(AM9,$F9,"") | AO9: =IF(AM9,AL9*correlation!$J$29,"") | AP9: =IF(AND(AM9,ISNUMBER(correlation!$F$29)),AO9*correlation!$F$29+correlation!$G$29,"") | AQ9: =IF(AND(AM9,ISNUMBER(AP9)),(AN9-AP9)^2,"") | AR9: =IF(AM9,1+SUMPRODUCT(--(calc!$AM$3:$AM$306=TRUE),--(calc!$AN$3:$AN$306>AN9))+(SUMPRODUCT(--(calc!$AM$3:$AM$306=TRUE),--(calc!$AN$3:$AN$306=AN9))-1)/2,"") | AS9: =IF(AM9,1+SUMPRODUCT(--(calc!$AM$3:$AM$306=TRUE),--(calc!$AO$3:$AO$306>AO9))+(SUMPRODUCT(--(calc!$AM$3:$AM$306=TRUE),--(calc!$AO$3:$AO$306=AO9))-1)/2,"") | AT9: =IF(AM9,SUMPRODUCT(--(calc!$AM$3:$AM$306=TRUE),--(ROW(calc!$AM$3:$AM$306)>ROW(AM9)),--(((calc!$AR$3:$AR$306>AR9)*(calc!$AS$3:$AS$306>AS9)+(calc!$AR$3:$AR$306<AR9)*(calc!$AS$3:$AS$306<AS9))>0))-SUMPRODUCT(--(calc!$AM$3:$AM$306=TRUE),--(ROW(calc!$AM$3:$AM$306)>ROW(AM9)),--(((calc!$AR$3:$AR$306>AR9)*(calc!$AS$3:$AS$306<AS9)+(calc!$AR$3:$AR$306<AR9)*(calc!$AS$3:$AS$306>AS9))>0)),0) | AU9: =IF(mos_metrics!K8="","",mos_metrics!K8) | AV9: =AND($J9,ISNUMBER(AU9),correlation!$I$30=1) | AW9: =IF(AV9,$F9,"") | AX9: =IF(AV9,AU9*correlation!$J$30,"") | AY9: =IF(AND(AV9,ISNUMBER(correlation!$F$30)),AX9*correlation!$F$30+correlation!$G$30,"") | AZ9: =IF(AND(AV9,ISNUMBER(AY9)),(AW9-AY9)^2,"") | BA9: =IF(AV9,1+SUMPRODUCT(--(calc!$AV$3:$AV$306=TRUE),--(calc!$AW$3:$AW$306>AW9))+(SUMPRODUCT(--(calc!$AV$3:$AV$306=TRUE),--(calc!$AW$3:$AW$306=AW9))-1)/2,"") | BB9: =IF(AV9,1+SUMPRODUCT(--(calc!$AV$3:$AV$306=TRUE),--(calc!$AX$3:$AX$306>AX9))+(SUMPRODUCT(--(calc!$AV$3:$AV$306=TRUE),--(calc!$AX$3:$AX$306=AX9))-1)/2,"") | BC9: =IF(AV9,SUMPRODUCT(--(calc!$AV$3:$AV$306=TRUE),--(ROW(calc!$AV$3:$AV$306)>ROW(AV9)),--(((calc!$BA$3:$BA$306>BA9)*(calc!$BB$3:$BB$306>BB9)+(calc!$BA$3:$BA$306<BA9)*(calc!$BB$3:$BB$306<BB9))>0))-SUMPRODUCT(--(calc!$AV$3:$AV$306=TRUE),--(ROW(calc!$AV$3:$AV$306)>ROW(AV9)),--(((calc!$BA$3:$BA$306>BA9)*(calc!$BB$3:$BB$306<BB9)+(calc!$BA$3:$BA$306<BA9)*(calc!$BB$3:$BB$306>BB9))>0)),0) | BD9: =IF(mos_metrics!L8="","",mos_metrics!L8) | BE9: =AND($J9,ISNUMBER(BD9),correlation!$I$31=1) | BF9: =IF(BE9,$F9,"") | BG9: =IF(BE9,BD9*correlation!$J$31,"") | BH9: =IF(AND(BE9,ISNUMBER(correlation!$F$31)),BG9*correlation!$F$31+correlation!$G$31,"") | BI9: =IF(AND(BE9,ISNUMBER(BH9)),(BF9-BH9)^2,"") | BJ9: =IF(BE9,1+SUMPRODUCT(--(calc!$BE$3:$BE$306=TRUE),--(calc!$BF$3:$BF$306>BF9))+(SUMPRODUCT(--(calc!$BE$3:$BE$306=TRUE),--(calc!$BF$3:$BF$306=BF9))-1)/2,"") | BK9: =IF(BE9,1+SUMPRODUCT(--(calc!$BE$3:$BE$306=TRUE),--(calc!$BG$3:$BG$306>BG9))+(SUMPRODUCT(--(calc!$BE$3:$BE$306=TRUE),--(calc!$BG$3:$BG$306=BG9))-1)/2,"") | BL9: =IF(BE9,SUMPRODUCT(--(calc!$BE$3:$BE$306=TRUE),--(ROW(calc!$BE$3:$BE$306)>ROW(BE9)),--(((calc!$BJ$3:$BJ$306>BJ9)*(calc!$BK$3:$BK$306>BK9)+(calc!$BJ$3:$BJ$306<BJ9)*(calc!$BK$3:$BK$306<BK9))>0))-SUMPRODUCT(--(calc!$BE$3:$BE$306=TRUE),--(ROW(calc!$BE$3:$BE$306)>ROW(BE9)),--(((calc!$BJ$3:$BJ$306>BJ9)*(calc!$BK$3:$BK$306<BK9)+(calc!$BJ$3:$BJ$306<BJ9)*(calc!$BK$3:$BK$306>BK9))>0)),0) | BM9: =IF(mos_metrics!M8="","",mos_metrics!M8) | BN9: =AND($J9,ISNUMBER(BM9),correlation!$I$32=1) | BO9: =IF(BN9,$F9,"") | BP9: =IF(BN9,BM9*correlation!$J$32,"") | BQ9: =IF(AND(BN9,ISNUMBER(correlation!$F$32)),BP9*correlation!$F$32+correlation!$G$32,"") | BR9: =IF(AND(BN9,ISNUMBER(BQ9)),(BO9-BQ9)^2,"") | BS9: =IF(BN9,1+SUMPRODUCT(--(calc!$BN$3:$BN$306=TRUE),--(calc!$BO$3:$BO$306>BO9))+(SUMPRODUCT(--(calc!$BN$3:$BN$306=TRUE),--(calc!$BO$3:$BO$306=BO9))-1)/2,"") | BT9: =IF(BN9,1+SUMPRODUCT(--(calc!$BN$3:$BN$306=TRUE),--(calc!$BP$3:$BP$306>BP9))+(SUMPRODUCT(--(calc!$BN$3:$BN$306=TRUE),--(calc!$BP$3:$BP$306=BP9))-1)/2,"") | BU9: =IF(BN9,SUMPRODUCT(--(calc!$BN$3:$BN$306=TRUE),--(ROW(calc!$BN$3:$BN$306)>ROW(BN9)),--(((calc!$BS$3:$BS$306>BS9)*(calc!$BT$3:$BT$306>BT9)+(calc!$BS$3:$BS$306<BS9)*(calc!$BT$3:$BT$306<BT9))>0))-SUMPRODUCT(--(calc!$BN$3:$BN$306=TRUE),--(ROW(calc!$BN$3:$BN$306)>ROW(BN9)),--(((calc!$BS$3:$BS$306>BS9)*(calc!$BT$3:$BT$306<BT9)+(calc!$BS$3:$BS$306<BS9)*(calc!$BT$3:$BT$306>BT9))>0)),0)
